[Wed Jul 08 22:16:02.098817 2020] [wsgi:error] [pid 31744] [client 165.84.106.3:54281] Truncated or oversized response headers received from daemon process 'nzhealth': /var/www/bcde215_assessment/django/nzhealth/nzhealth/wsgi.py
[Wed Jul 08 22:16:04.773444 2020] [wsgi:error] [pid 31945] [remote 165.84.106.3:54290] mod_wsgi (pid=31945): Target WSGI script '/var/www/bcde215_assessment/django/nzhealth/nzhealth/wsgi.py' cannot be loaded as Python module.
[Wed Jul 08 22:16:04.773509 2020] [wsgi:error] [pid 31945] [remote 165.84.106.3:54290] mod_wsgi (pid=31945): Exception occurred processing WSGI script '/var/www/bcde215_assessment/django/nzhealth/nzhealth/wsgi.py'.
[Wed Jul 08 22:16:04.791199 2020] [wsgi:error] [pid 31945] [remote 165.84.106.3:54290] Traceback (most recent call last):
[Wed Jul 08 22:16:04.791240 2020] [wsgi:error] [pid 31945] [remote 165.84.106.3:54290]   File "/var/www/bcde215_assessment/venv/lib/python3.6/site-packages/django/db/backends/mysql/base.py", line 16, in <module>
[Wed Jul 08 22:16:04.791246 2020] [wsgi:error] [pid 31945] [remote 165.84.106.3:54290]     import MySQLdb as Database
[Wed Jul 08 22:16:04.791265 2020] [wsgi:error] [pid 31945] [remote 165.84.106.3:54290] ModuleNotFoundError: No module named 'MySQLdb'
[Wed Jul 08 22:16:04.791275 2020] [wsgi:error] [pid 31945] [remote 165.84.106.3:54290] 
[Wed Jul 08 22:16:04.791279 2020] [wsgi:error] [pid 31945] [remote 165.84.106.3:54290] The above exception was the direct cause of the following exception:
[Wed Jul 08 22:16:04.791283 2020] [wsgi:error] [pid 31945] [remote 165.84.106.3:54290] 
[Wed Jul 08 22:16:04.791289 2020] [wsgi:error] [pid 31945] [remote 165.84.106.3:54290] Traceback (most recent call last):
[Wed Jul 08 22:16:04.791362 2020] [wsgi:error] [pid 31945] [remote 165.84.106.3:54290]   File "/var/www/bcde215_assessment/django/nzhealth/nzhealth/wsgi.py", line 16, in <module>
[Wed Jul 08 22:16:04.791368 2020] [wsgi:error] [pid 31945] [remote 165.84.106.3:54290]     application = get_wsgi_application()
[Wed Jul 08 22:16:04.791374 2020] [wsgi:error] [pid 31945] [remote 165.84.106.3:54290]   File "/var/www/bcde215_assessment/venv/lib/python3.6/site-packages/django/core/wsgi.py", line 12, in get_wsgi_application
[Wed Jul 08 22:16:04.791378 2020] [wsgi:error] [pid 31945] [remote 165.84.106.3:54290]     django.setup(set_prefix=False)
[Wed Jul 08 22:16:04.791385 2020] [wsgi:error] [pid 31945] [remote 165.84.106.3:54290]   File "/var/www/bcde215_assessment/venv/lib/python3.6/site-packages/django/__init__.py", line 24, in setup
[Wed Jul 08 22:16:04.791389 2020] [wsgi:error] [pid 31945] [remote 165.84.106.3:54290]     apps.populate(settings.INSTALLED_APPS)
[Wed Jul 08 22:16:04.791395 2020] [wsgi:error] [pid 31945] [remote 165.84.106.3:54290]   File "/var/www/bcde215_assessment/venv/lib/python3.6/site-packages/django/apps/registry.py", line 114, in populate
[Wed Jul 08 22:16:04.791399 2020] [wsgi:error] [pid 31945] [remote 165.84.106.3:54290]     app_config.import_models()
[Wed Jul 08 22:16:04.791405 2020] [wsgi:error] [pid 31945] [remote 165.84.106.3:54290]   File "/var/www/bcde215_assessment/venv/lib/python3.6/site-packages/django/apps/config.py", line 211, in import_models
[Wed Jul 08 22:16:04.791409 2020] [wsgi:error] [pid 31945] [remote 165.84.106.3:54290]     self.models_module = import_module(models_module_name)
[Wed Jul 08 22:16:04.791415 2020] [wsgi:error] [pid 31945] [remote 165.84.106.3:54290]   File "/usr/lib/python3.6/importlib/__init__.py", line 126, in import_module
[Wed Jul 08 22:16:04.791419 2020] [wsgi:error] [pid 31945] [remote 165.84.106.3:54290]     return _bootstrap._gcd_import(name[level:], package, level)
[Wed Jul 08 22:16:04.791425 2020] [wsgi:error] [pid 31945] [remote 165.84.106.3:54290]   File "<frozen importlib._bootstrap>", line 994, in _gcd_import
[Wed Jul 08 22:16:04.791431 2020] [wsgi:error] [pid 31945] [remote 165.84.106.3:54290]   File "<frozen importlib._bootstrap>", line 971, in _find_and_load
[Wed Jul 08 22:16:04.791436 2020] [wsgi:error] [pid 31945] [remote 165.84.106.3:54290]   File "<frozen importlib._bootstrap>", line 955, in _find_and_load_unlocked
[Wed Jul 08 22:16:04.791452 2020] [wsgi:error] [pid 31945] [remote 165.84.106.3:54290]   File "<frozen importlib._bootstrap>", line 665, in _load_unlocked
[Wed Jul 08 22:16:04.791458 2020] [wsgi:error] [pid 31945] [remote 165.84.106.3:54290]   File "<frozen importlib._bootstrap_external>", line 678, in exec_module
[Wed Jul 08 22:16:04.791464 2020] [wsgi:error] [pid 31945] [remote 165.84.106.3:54290]   File "<frozen importlib._bootstrap>", line 219, in _call_with_frames_removed
[Wed Jul 08 22:16:04.791470 2020] [wsgi:error] [pid 31945] [remote 165.84.106.3:54290]   File "/var/www/bcde215_assessment/venv/lib/python3.6/site-packages/django/contrib/auth/models.py", line 2, in <module>
[Wed Jul 08 22:16:04.791474 2020] [wsgi:error] [pid 31945] [remote 165.84.106.3:54290]     from django.contrib.auth.base_user import AbstractBaseUser, BaseUserManager
[Wed Jul 08 22:16:04.791480 2020] [wsgi:error] [pid 31945] [remote 165.84.106.3:54290]   File "/var/www/bcde215_assessment/venv/lib/python3.6/site-packages/django/contrib/auth/base_user.py", line 47, in <module>
[Wed Jul 08 22:16:04.791484 2020] [wsgi:error] [pid 31945] [remote 165.84.106.3:54290]     class AbstractBaseUser(models.Model):
[Wed Jul 08 22:16:04.791490 2020] [wsgi:error] [pid 31945] [remote 165.84.106.3:54290]   File "/var/www/bcde215_assessment/venv/lib/python3.6/site-packages/django/db/models/base.py", line 121, in __new__
[Wed Jul 08 22:16:04.791494 2020] [wsgi:error] [pid 31945] [remote 165.84.106.3:54290]     new_class.add_to_class('_meta', Options(meta, app_label))
[Wed Jul 08 22:16:04.791500 2020] [wsgi:error] [pid 31945] [remote 165.84.106.3:54290]   File "/var/www/bcde215_assessment/venv/lib/python3.6/site-packages/django/db/models/base.py", line 325, in add_to_class
[Wed Jul 08 22:16:04.791504 2020] [wsgi:error] [pid 31945] [remote 165.84.106.3:54290]     value.contribute_to_class(cls, name)
[Wed Jul 08 22:16:04.791510 2020] [wsgi:error] [pid 31945] [remote 165.84.106.3:54290]   File "/var/www/bcde215_assessment/venv/lib/python3.6/site-packages/django/db/models/options.py", line 208, in contribute_to_class
[Wed Jul 08 22:16:04.791514 2020] [wsgi:error] [pid 31945] [remote 165.84.106.3:54290]     self.db_table = truncate_name(self.db_table, connection.ops.max_name_length())
[Wed Jul 08 22:16:04.791520 2020] [wsgi:error] [pid 31945] [remote 165.84.106.3:54290]   File "/var/www/bcde215_assessment/venv/lib/python3.6/site-packages/django/db/__init__.py", line 28, in __getattr__
[Wed Jul 08 22:16:04.791524 2020] [wsgi:error] [pid 31945] [remote 165.84.106.3:54290]     return getattr(connections[DEFAULT_DB_ALIAS], item)
[Wed Jul 08 22:16:04.791530 2020] [wsgi:error] [pid 31945] [remote 165.84.106.3:54290]   File "/var/www/bcde215_assessment/venv/lib/python3.6/site-packages/django/db/utils.py", line 207, in __getitem__
[Wed Jul 08 22:16:04.791533 2020] [wsgi:error] [pid 31945] [remote 165.84.106.3:54290]     backend = load_backend(db['ENGINE'])
[Wed Jul 08 22:16:04.791539 2020] [wsgi:error] [pid 31945] [remote 165.84.106.3:54290]   File "/var/www/bcde215_assessment/venv/lib/python3.6/site-packages/django/db/utils.py", line 111, in load_backend
[Wed Jul 08 22:16:04.791543 2020] [wsgi:error] [pid 31945] [remote 165.84.106.3:54290]     return import_module('%s.base' % backend_name)
[Wed Jul 08 22:16:04.791549 2020] [wsgi:error] [pid 31945] [remote 165.84.106.3:54290]   File "/usr/lib/python3.6/importlib/__init__.py", line 126, in import_module
[Wed Jul 08 22:16:04.791553 2020] [wsgi:error] [pid 31945] [remote 165.84.106.3:54290]     return _bootstrap._gcd_import(name[level:], package, level)
[Wed Jul 08 22:16:04.791559 2020] [wsgi:error] [pid 31945] [remote 165.84.106.3:54290]   File "/var/www/bcde215_assessment/venv/lib/python3.6/site-packages/django/db/backends/mysql/base.py", line 21, in <module>
[Wed Jul 08 22:16:04.791563 2020] [wsgi:error] [pid 31945] [remote 165.84.106.3:54290]     ) from err
[Wed Jul 08 22:16:04.791577 2020] [wsgi:error] [pid 31945] [remote 165.84.106.3:54290] django.core.exceptions.ImproperlyConfigured: Error loading MySQLdb module.
[Wed Jul 08 22:16:04.791585 2020] [wsgi:error] [pid 31945] [remote 165.84.106.3:54290] Did you install mysqlclient?
[Wed Jul 08 22:16:06.326512 2020] [wsgi:error] [pid 31945] [remote 165.84.106.3:54291] mod_wsgi (pid=31945): Target WSGI script '/var/www/bcde215_assessment/django/nzhealth/nzhealth/wsgi.py' cannot be loaded as Python module.
[Wed Jul 08 22:16:06.326566 2020] [wsgi:error] [pid 31945] [remote 165.84.106.3:54291] mod_wsgi (pid=31945): Exception occurred processing WSGI script '/var/www/bcde215_assessment/django/nzhealth/nzhealth/wsgi.py'.
[Wed Jul 08 22:16:06.326679 2020] [wsgi:error] [pid 31945] [remote 165.84.106.3:54291] Traceback (most recent call last):
[Wed Jul 08 22:16:06.326717 2020] [wsgi:error] [pid 31945] [remote 165.84.106.3:54291]   File "/var/www/bcde215_assessment/django/nzhealth/nzhealth/wsgi.py", line 16, in <module>
[Wed Jul 08 22:16:06.326723 2020] [wsgi:error] [pid 31945] [remote 165.84.106.3:54291]     application = get_wsgi_application()
[Wed Jul 08 22:16:06.326754 2020] [wsgi:error] [pid 31945] [remote 165.84.106.3:54291]   File "/var/www/bcde215_assessment/venv/lib/python3.6/site-packages/django/core/wsgi.py", line 12, in get_wsgi_application
[Wed Jul 08 22:16:06.326800 2020] [wsgi:error] [pid 31945] [remote 165.84.106.3:54291]     django.setup(set_prefix=False)
[Wed Jul 08 22:16:06.326814 2020] [wsgi:error] [pid 31945] [remote 165.84.106.3:54291]   File "/var/www/bcde215_assessment/venv/lib/python3.6/site-packages/django/__init__.py", line 24, in setup
[Wed Jul 08 22:16:06.326819 2020] [wsgi:error] [pid 31945] [remote 165.84.106.3:54291]     apps.populate(settings.INSTALLED_APPS)
[Wed Jul 08 22:16:06.326825 2020] [wsgi:error] [pid 31945] [remote 165.84.106.3:54291]   File "/var/www/bcde215_assessment/venv/lib/python3.6/site-packages/django/apps/registry.py", line 83, in populate
[Wed Jul 08 22:16:06.326829 2020] [wsgi:error] [pid 31945] [remote 165.84.106.3:54291]     raise RuntimeError("populate() isn't reentrant")
[Wed Jul 08 22:16:06.326847 2020] [wsgi:error] [pid 31945] [remote 165.84.106.3:54291] RuntimeError: populate() isn't reentrant
[Wed Jul 08 22:16:12.449280 2020] [wsgi:error] [pid 31945] [remote 165.84.106.3:54292] mod_wsgi (pid=31945): Target WSGI script '/var/www/bcde215_assessment/django/nzhealth/nzhealth/wsgi.py' cannot be loaded as Python module.
[Wed Jul 08 22:16:12.449333 2020] [wsgi:error] [pid 31945] [remote 165.84.106.3:54292] mod_wsgi (pid=31945): Exception occurred processing WSGI script '/var/www/bcde215_assessment/django/nzhealth/nzhealth/wsgi.py'.
[Wed Jul 08 22:16:12.449441 2020] [wsgi:error] [pid 31945] [remote 165.84.106.3:54292] Traceback (most recent call last):
[Wed Jul 08 22:16:12.449474 2020] [wsgi:error] [pid 31945] [remote 165.84.106.3:54292]   File "/var/www/bcde215_assessment/django/nzhealth/nzhealth/wsgi.py", line 16, in <module>
[Wed Jul 08 22:16:12.449480 2020] [wsgi:error] [pid 31945] [remote 165.84.106.3:54292]     application = get_wsgi_application()
[Wed Jul 08 22:16:12.449487 2020] [wsgi:error] [pid 31945] [remote 165.84.106.3:54292]   File "/var/www/bcde215_assessment/venv/lib/python3.6/site-packages/django/core/wsgi.py", line 12, in get_wsgi_application
[Wed Jul 08 22:16:12.449491 2020] [wsgi:error] [pid 31945] [remote 165.84.106.3:54292]     django.setup(set_prefix=False)
[Wed Jul 08 22:16:12.449498 2020] [wsgi:error] [pid 31945] [remote 165.84.106.3:54292]   File "/var/www/bcde215_assessment/venv/lib/python3.6/site-packages/django/__init__.py", line 24, in setup
[Wed Jul 08 22:16:12.449502 2020] [wsgi:error] [pid 31945] [remote 165.84.106.3:54292]     apps.populate(settings.INSTALLED_APPS)
[Wed Jul 08 22:16:12.449508 2020] [wsgi:error] [pid 31945] [remote 165.84.106.3:54292]   File "/var/www/bcde215_assessment/venv/lib/python3.6/site-packages/django/apps/registry.py", line 83, in populate
[Wed Jul 08 22:16:12.449512 2020] [wsgi:error] [pid 31945] [remote 165.84.106.3:54292]     raise RuntimeError("populate() isn't reentrant")
[Wed Jul 08 22:16:12.449528 2020] [wsgi:error] [pid 31945] [remote 165.84.106.3:54292] RuntimeError: populate() isn't reentrant
[Wed Jul 08 22:16:13.382313 2020] [wsgi:error] [pid 31945] [remote 165.84.106.3:54293] mod_wsgi (pid=31945): Target WSGI script '/var/www/bcde215_assessment/django/nzhealth/nzhealth/wsgi.py' cannot be loaded as Python module.
[Wed Jul 08 22:16:13.385192 2020] [wsgi:error] [pid 31945] [remote 165.84.106.3:54293] mod_wsgi (pid=31945): Exception occurred processing WSGI script '/var/www/bcde215_assessment/django/nzhealth/nzhealth/wsgi.py'.
[Wed Jul 08 22:16:13.385315 2020] [wsgi:error] [pid 31945] [remote 165.84.106.3:54293] Traceback (most recent call last):
[Wed Jul 08 22:16:13.385350 2020] [wsgi:error] [pid 31945] [remote 165.84.106.3:54293]   File "/var/www/bcde215_assessment/django/nzhealth/nzhealth/wsgi.py", line 16, in <module>
[Wed Jul 08 22:16:13.385355 2020] [wsgi:error] [pid 31945] [remote 165.84.106.3:54293]     application = get_wsgi_application()
[Wed Jul 08 22:16:13.385362 2020] [wsgi:error] [pid 31945] [remote 165.84.106.3:54293]   File "/var/www/bcde215_assessment/venv/lib/python3.6/site-packages/django/core/wsgi.py", line 12, in get_wsgi_application
[Wed Jul 08 22:16:13.385366 2020] [wsgi:error] [pid 31945] [remote 165.84.106.3:54293]     django.setup(set_prefix=False)
[Wed Jul 08 22:16:13.385373 2020] [wsgi:error] [pid 31945] [remote 165.84.106.3:54293]   File "/var/www/bcde215_assessment/venv/lib/python3.6/site-packages/django/__init__.py", line 24, in setup
[Wed Jul 08 22:16:13.385377 2020] [wsgi:error] [pid 31945] [remote 165.84.106.3:54293]     apps.populate(settings.INSTALLED_APPS)
[Wed Jul 08 22:16:13.385384 2020] [wsgi:error] [pid 31945] [remote 165.84.106.3:54293]   File "/var/www/bcde215_assessment/venv/lib/python3.6/site-packages/django/apps/registry.py", line 83, in populate
[Wed Jul 08 22:16:13.385388 2020] [wsgi:error] [pid 31945] [remote 165.84.106.3:54293]     raise RuntimeError("populate() isn't reentrant")
[Wed Jul 08 22:16:13.385403 2020] [wsgi:error] [pid 31945] [remote 165.84.106.3:54293] RuntimeError: populate() isn't reentrant
Exception ignored in: <bound method BaseEventLoop.__del__ of <_UnixSelectorEventLoop running=False closed=False debug=False>>
Traceback (most recent call last):
  File "/usr/lib/python3.6/asyncio/base_events.py", line 526, in __del__
NameError: name 'ResourceWarning' is not defined
[Wed Jul 08 22:17:01.080246 2020] [wsgi:error] [pid 32008] [remote 165.84.106.3:54299] mod_wsgi (pid=32008): Target WSGI script '/var/www/bcde215_assessment/django/nzhealth/nzhealth/wsgi.py' cannot be loaded as Python module.
[Wed Jul 08 22:17:01.080319 2020] [wsgi:error] [pid 32008] [remote 165.84.106.3:54299] mod_wsgi (pid=32008): Exception occurred processing WSGI script '/var/www/bcde215_assessment/django/nzhealth/nzhealth/wsgi.py'.
[Wed Jul 08 22:17:01.082163 2020] [wsgi:error] [pid 32008] [remote 165.84.106.3:54299] Traceback (most recent call last):
[Wed Jul 08 22:17:01.082194 2020] [wsgi:error] [pid 32008] [remote 165.84.106.3:54299]   File "/var/www/bcde215_assessment/venv/lib/python3.6/site-packages/django/db/backends/mysql/base.py", line 16, in <module>
[Wed Jul 08 22:17:01.082200 2020] [wsgi:error] [pid 32008] [remote 165.84.106.3:54299]     import MySQLdb as Database
[Wed Jul 08 22:17:01.082217 2020] [wsgi:error] [pid 32008] [remote 165.84.106.3:54299] ModuleNotFoundError: No module named 'MySQLdb'
[Wed Jul 08 22:17:01.082226 2020] [wsgi:error] [pid 32008] [remote 165.84.106.3:54299] 
[Wed Jul 08 22:17:01.082230 2020] [wsgi:error] [pid 32008] [remote 165.84.106.3:54299] The above exception was the direct cause of the following exception:
[Wed Jul 08 22:17:01.082234 2020] [wsgi:error] [pid 32008] [remote 165.84.106.3:54299] 
[Wed Jul 08 22:17:01.082241 2020] [wsgi:error] [pid 32008] [remote 165.84.106.3:54299] Traceback (most recent call last):
[Wed Jul 08 22:17:01.082310 2020] [wsgi:error] [pid 32008] [remote 165.84.106.3:54299]   File "/var/www/bcde215_assessment/django/nzhealth/nzhealth/wsgi.py", line 16, in <module>
[Wed Jul 08 22:17:01.082316 2020] [wsgi:error] [pid 32008] [remote 165.84.106.3:54299]     application = get_wsgi_application()
[Wed Jul 08 22:17:01.082333 2020] [wsgi:error] [pid 32008] [remote 165.84.106.3:54299]   File "/var/www/bcde215_assessment/venv/lib/python3.6/site-packages/django/core/wsgi.py", line 12, in get_wsgi_application
[Wed Jul 08 22:17:01.082338 2020] [wsgi:error] [pid 32008] [remote 165.84.106.3:54299]     django.setup(set_prefix=False)
[Wed Jul 08 22:17:01.082344 2020] [wsgi:error] [pid 32008] [remote 165.84.106.3:54299]   File "/var/www/bcde215_assessment/venv/lib/python3.6/site-packages/django/__init__.py", line 24, in setup
[Wed Jul 08 22:17:01.082348 2020] [wsgi:error] [pid 32008] [remote 165.84.106.3:54299]     apps.populate(settings.INSTALLED_APPS)
[Wed Jul 08 22:17:01.082354 2020] [wsgi:error] [pid 32008] [remote 165.84.106.3:54299]   File "/var/www/bcde215_assessment/venv/lib/python3.6/site-packages/django/apps/registry.py", line 114, in populate
[Wed Jul 08 22:17:01.082358 2020] [wsgi:error] [pid 32008] [remote 165.84.106.3:54299]     app_config.import_models()
[Wed Jul 08 22:17:01.082364 2020] [wsgi:error] [pid 32008] [remote 165.84.106.3:54299]   File "/var/www/bcde215_assessment/venv/lib/python3.6/site-packages/django/apps/config.py", line 211, in import_models
[Wed Jul 08 22:17:01.082368 2020] [wsgi:error] [pid 32008] [remote 165.84.106.3:54299]     self.models_module = import_module(models_module_name)
[Wed Jul 08 22:17:01.082374 2020] [wsgi:error] [pid 32008] [remote 165.84.106.3:54299]   File "/usr/lib/python3.6/importlib/__init__.py", line 126, in import_module
[Wed Jul 08 22:17:01.082378 2020] [wsgi:error] [pid 32008] [remote 165.84.106.3:54299]     return _bootstrap._gcd_import(name[level:], package, level)
[Wed Jul 08 22:17:01.082384 2020] [wsgi:error] [pid 32008] [remote 165.84.106.3:54299]   File "<frozen importlib._bootstrap>", line 994, in _gcd_import
[Wed Jul 08 22:17:01.082390 2020] [wsgi:error] [pid 32008] [remote 165.84.106.3:54299]   File "<frozen importlib._bootstrap>", line 971, in _find_and_load
[Wed Jul 08 22:17:01.082396 2020] [wsgi:error] [pid 32008] [remote 165.84.106.3:54299]   File "<frozen importlib._bootstrap>", line 955, in _find_and_load_unlocked
[Wed Jul 08 22:17:01.082402 2020] [wsgi:error] [pid 32008] [remote 165.84.106.3:54299]   File "<frozen importlib._bootstrap>", line 665, in _load_unlocked
[Wed Jul 08 22:17:01.082408 2020] [wsgi:error] [pid 32008] [remote 165.84.106.3:54299]   File "<frozen importlib._bootstrap_external>", line 678, in exec_module
[Wed Jul 08 22:17:01.082414 2020] [wsgi:error] [pid 32008] [remote 165.84.106.3:54299]   File "<frozen importlib._bootstrap>", line 219, in _call_with_frames_removed
[Wed Jul 08 22:17:01.082420 2020] [wsgi:error] [pid 32008] [remote 165.84.106.3:54299]   File "/var/www/bcde215_assessment/venv/lib/python3.6/site-packages/django/contrib/auth/models.py", line 2, in <module>
[Wed Jul 08 22:17:01.082424 2020] [wsgi:error] [pid 32008] [remote 165.84.106.3:54299]     from django.contrib.auth.base_user import AbstractBaseUser, BaseUserManager
[Wed Jul 08 22:17:01.082430 2020] [wsgi:error] [pid 32008] [remote 165.84.106.3:54299]   File "/var/www/bcde215_assessment/venv/lib/python3.6/site-packages/django/contrib/auth/base_user.py", line 47, in <module>
[Wed Jul 08 22:17:01.082434 2020] [wsgi:error] [pid 32008] [remote 165.84.106.3:54299]     class AbstractBaseUser(models.Model):
[Wed Jul 08 22:17:01.082440 2020] [wsgi:error] [pid 32008] [remote 165.84.106.3:54299]   File "/var/www/bcde215_assessment/venv/lib/python3.6/site-packages/django/db/models/base.py", line 121, in __new__
[Wed Jul 08 22:17:01.082443 2020] [wsgi:error] [pid 32008] [remote 165.84.106.3:54299]     new_class.add_to_class('_meta', Options(meta, app_label))
[Wed Jul 08 22:17:01.082449 2020] [wsgi:error] [pid 32008] [remote 165.84.106.3:54299]   File "/var/www/bcde215_assessment/venv/lib/python3.6/site-packages/django/db/models/base.py", line 325, in add_to_class
[Wed Jul 08 22:17:01.082453 2020] [wsgi:error] [pid 32008] [remote 165.84.106.3:54299]     value.contribute_to_class(cls, name)
[Wed Jul 08 22:17:01.082459 2020] [wsgi:error] [pid 32008] [remote 165.84.106.3:54299]   File "/var/www/bcde215_assessment/venv/lib/python3.6/site-packages/django/db/models/options.py", line 208, in contribute_to_class
[Wed Jul 08 22:17:01.082467 2020] [wsgi:error] [pid 32008] [remote 165.84.106.3:54299]     self.db_table = truncate_name(self.db_table, connection.ops.max_name_length())
[Wed Jul 08 22:17:01.082473 2020] [wsgi:error] [pid 32008] [remote 165.84.106.3:54299]   File "/var/www/bcde215_assessment/venv/lib/python3.6/site-packages/django/db/__init__.py", line 28, in __getattr__
[Wed Jul 08 22:17:01.082477 2020] [wsgi:error] [pid 32008] [remote 165.84.106.3:54299]     return getattr(connections[DEFAULT_DB_ALIAS], item)
[Wed Jul 08 22:17:01.082483 2020] [wsgi:error] [pid 32008] [remote 165.84.106.3:54299]   File "/var/www/bcde215_assessment/venv/lib/python3.6/site-packages/django/db/utils.py", line 207, in __getitem__
[Wed Jul 08 22:17:01.082487 2020] [wsgi:error] [pid 32008] [remote 165.84.106.3:54299]     backend = load_backend(db['ENGINE'])
[Wed Jul 08 22:17:01.082493 2020] [wsgi:error] [pid 32008] [remote 165.84.106.3:54299]   File "/var/www/bcde215_assessment/venv/lib/python3.6/site-packages/django/db/utils.py", line 111, in load_backend
[Wed Jul 08 22:17:01.082497 2020] [wsgi:error] [pid 32008] [remote 165.84.106.3:54299]     return import_module('%s.base' % backend_name)
[Wed Jul 08 22:17:01.082502 2020] [wsgi:error] [pid 32008] [remote 165.84.106.3:54299]   File "/usr/lib/python3.6/importlib/__init__.py", line 126, in import_module
[Wed Jul 08 22:17:01.082506 2020] [wsgi:error] [pid 32008] [remote 165.84.106.3:54299]     return _bootstrap._gcd_import(name[level:], package, level)
[Wed Jul 08 22:17:01.082512 2020] [wsgi:error] [pid 32008] [remote 165.84.106.3:54299]   File "/var/www/bcde215_assessment/venv/lib/python3.6/site-packages/django/db/backends/mysql/base.py", line 21, in <module>
[Wed Jul 08 22:17:01.082516 2020] [wsgi:error] [pid 32008] [remote 165.84.106.3:54299]     ) from err
[Wed Jul 08 22:17:01.082529 2020] [wsgi:error] [pid 32008] [remote 165.84.106.3:54299] django.core.exceptions.ImproperlyConfigured: Error loading MySQLdb module.
[Wed Jul 08 22:17:01.082533 2020] [wsgi:error] [pid 32008] [remote 165.84.106.3:54299] Did you install mysqlclient?
[Wed Jul 08 22:26:18.280139 2020] [wsgi:error] [pid 32008] [remote 165.84.106.3:54380] mod_wsgi (pid=32008): Target WSGI script '/var/www/bcde215_assessment/django/nzhealth/nzhealth/wsgi.py' cannot be loaded as Python module.
[Wed Jul 08 22:26:18.280201 2020] [wsgi:error] [pid 32008] [remote 165.84.106.3:54380] mod_wsgi (pid=32008): Exception occurred processing WSGI script '/var/www/bcde215_assessment/django/nzhealth/nzhealth/wsgi.py'.
[Wed Jul 08 22:26:18.280307 2020] [wsgi:error] [pid 32008] [remote 165.84.106.3:54380] Traceback (most recent call last):
[Wed Jul 08 22:26:18.280343 2020] [wsgi:error] [pid 32008] [remote 165.84.106.3:54380]   File "/var/www/bcde215_assessment/django/nzhealth/nzhealth/wsgi.py", line 16, in <module>
[Wed Jul 08 22:26:18.280348 2020] [wsgi:error] [pid 32008] [remote 165.84.106.3:54380]     application = get_wsgi_application()
[Wed Jul 08 22:26:18.280355 2020] [wsgi:error] [pid 32008] [remote 165.84.106.3:54380]   File "/var/www/bcde215_assessment/venv/lib/python3.6/site-packages/django/core/wsgi.py", line 12, in get_wsgi_application
[Wed Jul 08 22:26:18.280360 2020] [wsgi:error] [pid 32008] [remote 165.84.106.3:54380]     django.setup(set_prefix=False)
[Wed Jul 08 22:26:18.280366 2020] [wsgi:error] [pid 32008] [remote 165.84.106.3:54380]   File "/var/www/bcde215_assessment/venv/lib/python3.6/site-packages/django/__init__.py", line 24, in setup
[Wed Jul 08 22:26:18.280370 2020] [wsgi:error] [pid 32008] [remote 165.84.106.3:54380]     apps.populate(settings.INSTALLED_APPS)
[Wed Jul 08 22:26:18.280377 2020] [wsgi:error] [pid 32008] [remote 165.84.106.3:54380]   File "/var/www/bcde215_assessment/venv/lib/python3.6/site-packages/django/apps/registry.py", line 83, in populate
[Wed Jul 08 22:26:18.280392 2020] [wsgi:error] [pid 32008] [remote 165.84.106.3:54380]     raise RuntimeError("populate() isn't reentrant")
[Wed Jul 08 22:26:18.280431 2020] [wsgi:error] [pid 32008] [remote 165.84.106.3:54380] RuntimeError: populate() isn't reentrant
Exception ignored in: <bound method BaseEventLoop.__del__ of <_UnixSelectorEventLoop running=False closed=False debug=False>>
Traceback (most recent call last):
  File "/usr/lib/python3.6/asyncio/base_events.py", line 526, in __del__
NameError: name 'ResourceWarning' is not defined
Exception ignored in: <bound method BaseEventLoop.__del__ of <_UnixSelectorEventLoop running=False closed=False debug=False>>
Traceback (most recent call last):
  File "/usr/lib/python3.6/asyncio/base_events.py", line 526, in __del__
NameError: name 'ResourceWarning' is not defined
[Wed Jul 08 22:38:59.016342 2020] [wsgi:error] [pid 1756] [remote 165.84.106.3:54504] Not Found: /favicon.ico
[Thu Jul 09 01:01:45.236753 2020] [wsgi:error] [pid 1756] [remote 165.84.106.3:54565] Not Found: /show
[Thu Jul 09 01:02:15.788977 2020] [wsgi:error] [pid 1756] [remote 165.84.106.3:54572] Not Found: /emp
[Thu Jul 09 01:05:15.549024 2020] [wsgi:error] [pid 1756] [remote 165.84.106.3:54597] Not Found: /show
[Thu Jul 09 01:06:12.747412 2020] [wsgi:error] [pid 1756] [remote 165.84.106.3:54601] Not Found: /show
[Thu Jul 09 01:09:46.381253 2020] [wsgi:error] [pid 1756] [remote 165.84.106.3:54643] Not Found: /show
[Thu Jul 09 01:09:47.536692 2020] [wsgi:error] [pid 1756] [remote 165.84.106.3:54643] Not Found: /show
Exception ignored in: <bound method BaseEventLoop.__del__ of <_UnixSelectorEventLoop running=False closed=False debug=False>>
Traceback (most recent call last):
  File "/usr/lib/python3.6/asyncio/base_events.py", line 526, in __del__
NameError: name 'ResourceWarning' is not defined
[Thu Jul 09 01:10:12.431984 2020] [wsgi:error] [pid 2560] [remote 165.84.106.3:54646] Internal Server Error: /show
[Thu Jul 09 01:10:12.432036 2020] [wsgi:error] [pid 2560] [remote 165.84.106.3:54646] Traceback (most recent call last):
[Thu Jul 09 01:10:12.432041 2020] [wsgi:error] [pid 2560] [remote 165.84.106.3:54646]   File "/var/www/bcde215_assessment/venv/lib/python3.6/site-packages/django/template/defaulttags.py", line 1021, in find_library
[Thu Jul 09 01:10:12.432046 2020] [wsgi:error] [pid 2560] [remote 165.84.106.3:54646]     return parser.libraries[name]
[Thu Jul 09 01:10:12.432050 2020] [wsgi:error] [pid 2560] [remote 165.84.106.3:54646] KeyError: 'statics'
[Thu Jul 09 01:10:12.432054 2020] [wsgi:error] [pid 2560] [remote 165.84.106.3:54646] 
[Thu Jul 09 01:10:12.432058 2020] [wsgi:error] [pid 2560] [remote 165.84.106.3:54646] During handling of the above exception, another exception occurred:
[Thu Jul 09 01:10:12.432062 2020] [wsgi:error] [pid 2560] [remote 165.84.106.3:54646] 
[Thu Jul 09 01:10:12.432066 2020] [wsgi:error] [pid 2560] [remote 165.84.106.3:54646] Traceback (most recent call last):
[Thu Jul 09 01:10:12.432070 2020] [wsgi:error] [pid 2560] [remote 165.84.106.3:54646]   File "/var/www/bcde215_assessment/venv/lib/python3.6/site-packages/django/core/handlers/exception.py", line 34, in inner
[Thu Jul 09 01:10:12.432074 2020] [wsgi:error] [pid 2560] [remote 165.84.106.3:54646]     response = get_response(request)
[Thu Jul 09 01:10:12.432078 2020] [wsgi:error] [pid 2560] [remote 165.84.106.3:54646]   File "/var/www/bcde215_assessment/venv/lib/python3.6/site-packages/django/core/handlers/base.py", line 115, in _get_response
[Thu Jul 09 01:10:12.432083 2020] [wsgi:error] [pid 2560] [remote 165.84.106.3:54646]     response = self.process_exception_by_middleware(e, request)
[Thu Jul 09 01:10:12.432087 2020] [wsgi:error] [pid 2560] [remote 165.84.106.3:54646]   File "/var/www/bcde215_assessment/venv/lib/python3.6/site-packages/django/core/handlers/base.py", line 113, in _get_response
[Thu Jul 09 01:10:12.432091 2020] [wsgi:error] [pid 2560] [remote 165.84.106.3:54646]     response = wrapped_callback(request, *callback_args, **callback_kwargs)
[Thu Jul 09 01:10:12.432096 2020] [wsgi:error] [pid 2560] [remote 165.84.106.3:54646]   File "/var/www/bcde215_assessment/django/nzhealth/covid_cms/views.py", line 18, in show
[Thu Jul 09 01:10:12.432112 2020] [wsgi:error] [pid 2560] [remote 165.84.106.3:54646]     return render(request,"show.html",{'referrals':referrals})
[Thu Jul 09 01:10:12.432116 2020] [wsgi:error] [pid 2560] [remote 165.84.106.3:54646]   File "/var/www/bcde215_assessment/venv/lib/python3.6/site-packages/django/shortcuts.py", line 19, in render
[Thu Jul 09 01:10:12.432120 2020] [wsgi:error] [pid 2560] [remote 165.84.106.3:54646]     content = loader.render_to_string(template_name, context, request, using=using)
[Thu Jul 09 01:10:12.432124 2020] [wsgi:error] [pid 2560] [remote 165.84.106.3:54646]   File "/var/www/bcde215_assessment/venv/lib/python3.6/site-packages/django/template/loader.py", line 61, in render_to_string
[Thu Jul 09 01:10:12.432128 2020] [wsgi:error] [pid 2560] [remote 165.84.106.3:54646]     template = get_template(template_name, using=using)
[Thu Jul 09 01:10:12.432131 2020] [wsgi:error] [pid 2560] [remote 165.84.106.3:54646]   File "/var/www/bcde215_assessment/venv/lib/python3.6/site-packages/django/template/loader.py", line 15, in get_template
[Thu Jul 09 01:10:12.432135 2020] [wsgi:error] [pid 2560] [remote 165.84.106.3:54646]     return engine.get_template(template_name)
[Thu Jul 09 01:10:12.432139 2020] [wsgi:error] [pid 2560] [remote 165.84.106.3:54646]   File "/var/www/bcde215_assessment/venv/lib/python3.6/site-packages/django/template/backends/django.py", line 34, in get_template
[Thu Jul 09 01:10:12.432143 2020] [wsgi:error] [pid 2560] [remote 165.84.106.3:54646]     return Template(self.engine.get_template(template_name), self)
[Thu Jul 09 01:10:12.432146 2020] [wsgi:error] [pid 2560] [remote 165.84.106.3:54646]   File "/var/www/bcde215_assessment/venv/lib/python3.6/site-packages/django/template/engine.py", line 143, in get_template
[Thu Jul 09 01:10:12.432150 2020] [wsgi:error] [pid 2560] [remote 165.84.106.3:54646]     template, origin = self.find_template(template_name)
[Thu Jul 09 01:10:12.432154 2020] [wsgi:error] [pid 2560] [remote 165.84.106.3:54646]   File "/var/www/bcde215_assessment/venv/lib/python3.6/site-packages/django/template/engine.py", line 125, in find_template
[Thu Jul 09 01:10:12.432157 2020] [wsgi:error] [pid 2560] [remote 165.84.106.3:54646]     template = loader.get_template(name, skip=skip)
[Thu Jul 09 01:10:12.432161 2020] [wsgi:error] [pid 2560] [remote 165.84.106.3:54646]   File "/var/www/bcde215_assessment/venv/lib/python3.6/site-packages/django/template/loaders/base.py", line 30, in get_template
[Thu Jul 09 01:10:12.432165 2020] [wsgi:error] [pid 2560] [remote 165.84.106.3:54646]     contents, origin, origin.template_name, self.engine,
[Thu Jul 09 01:10:12.432169 2020] [wsgi:error] [pid 2560] [remote 165.84.106.3:54646]   File "/var/www/bcde215_assessment/venv/lib/python3.6/site-packages/django/template/base.py", line 156, in __init__
[Thu Jul 09 01:10:12.432172 2020] [wsgi:error] [pid 2560] [remote 165.84.106.3:54646]     self.nodelist = self.compile_nodelist()
[Thu Jul 09 01:10:12.432176 2020] [wsgi:error] [pid 2560] [remote 165.84.106.3:54646]   File "/var/www/bcde215_assessment/venv/lib/python3.6/site-packages/django/template/base.py", line 194, in compile_nodelist
[Thu Jul 09 01:10:12.432180 2020] [wsgi:error] [pid 2560] [remote 165.84.106.3:54646]     return parser.parse()
[Thu Jul 09 01:10:12.432183 2020] [wsgi:error] [pid 2560] [remote 165.84.106.3:54646]   File "/var/www/bcde215_assessment/venv/lib/python3.6/site-packages/django/template/base.py", line 477, in parse
[Thu Jul 09 01:10:12.432187 2020] [wsgi:error] [pid 2560] [remote 165.84.106.3:54646]     raise self.error(token, e)
[Thu Jul 09 01:10:12.432191 2020] [wsgi:error] [pid 2560] [remote 165.84.106.3:54646]   File "/var/www/bcde215_assessment/venv/lib/python3.6/site-packages/django/template/base.py", line 475, in parse
[Thu Jul 09 01:10:12.432194 2020] [wsgi:error] [pid 2560] [remote 165.84.106.3:54646]     compiled_result = compile_func(self, token)
[Thu Jul 09 01:10:12.432198 2020] [wsgi:error] [pid 2560] [remote 165.84.106.3:54646]   File "/var/www/bcde215_assessment/venv/lib/python3.6/site-packages/django/template/defaulttags.py", line 1078, in load
[Thu Jul 09 01:10:12.432208 2020] [wsgi:error] [pid 2560] [remote 165.84.106.3:54646]     lib = find_library(parser, name)
[Thu Jul 09 01:10:12.432212 2020] [wsgi:error] [pid 2560] [remote 165.84.106.3:54646]   File "/var/www/bcde215_assessment/venv/lib/python3.6/site-packages/django/template/defaulttags.py", line 1025, in find_library
[Thu Jul 09 01:10:12.432215 2020] [wsgi:error] [pid 2560] [remote 165.84.106.3:54646]     name, "\\n".join(sorted(parser.libraries)),
[Thu Jul 09 01:10:12.432219 2020] [wsgi:error] [pid 2560] [remote 165.84.106.3:54646] django.template.exceptions.TemplateSyntaxError: 'statics' is not a registered tag library. Must be one of:
[Thu Jul 09 01:10:12.432223 2020] [wsgi:error] [pid 2560] [remote 165.84.106.3:54646] admin_list
[Thu Jul 09 01:10:12.432226 2020] [wsgi:error] [pid 2560] [remote 165.84.106.3:54646] admin_modify
[Thu Jul 09 01:10:12.432230 2020] [wsgi:error] [pid 2560] [remote 165.84.106.3:54646] admin_urls
[Thu Jul 09 01:10:12.432233 2020] [wsgi:error] [pid 2560] [remote 165.84.106.3:54646] cache
[Thu Jul 09 01:10:12.432237 2020] [wsgi:error] [pid 2560] [remote 165.84.106.3:54646] i18n
[Thu Jul 09 01:10:12.432240 2020] [wsgi:error] [pid 2560] [remote 165.84.106.3:54646] l10n
[Thu Jul 09 01:10:12.432243 2020] [wsgi:error] [pid 2560] [remote 165.84.106.3:54646] log
[Thu Jul 09 01:10:12.432247 2020] [wsgi:error] [pid 2560] [remote 165.84.106.3:54646] static
[Thu Jul 09 01:10:12.432252 2020] [wsgi:error] [pid 2560] [remote 165.84.106.3:54646] tz
[Thu Jul 09 01:10:12.432259 2020] [wsgi:error] [pid 2560] [remote 165.84.106.3:54646] 
[Thu Jul 09 01:10:48.773985 2020] [wsgi:error] [pid 2560] [remote 165.84.106.3:54648] Not Found: /
[Thu Jul 09 01:11:02.695160 2020] [wsgi:error] [pid 2560] [remote 165.84.106.3:54650] Not Found: /images/logo.jpg
[Thu Jul 09 01:11:02.742145 2020] [wsgi:error] [pid 2560] [remote 165.84.106.3:54651] Not Found: /images/welcome-image.jpg
[Thu Jul 09 01:11:17.320070 2020] [wsgi:error] [pid 2560] [remote 165.84.106.3:54653] Not Found: /
[Thu Jul 09 01:11:18.719659 2020] [wsgi:error] [pid 2560] [remote 165.84.106.3:54653] Not Found: /images/logo.jpg
[Thu Jul 09 01:11:18.768757 2020] [wsgi:error] [pid 2560] [remote 165.84.106.3:54653] Not Found: /images/welcome-image.jpg
[Thu Jul 09 01:11:22.114806 2020] [wsgi:error] [pid 2560] [remote 165.84.106.3:54653] Not Found: /index.html
[Thu Jul 09 01:11:23.822595 2020] [wsgi:error] [pid 2560] [remote 165.84.106.3:54653] Not Found: /images/welcome-image.jpg
[Thu Jul 09 01:11:23.823069 2020] [wsgi:error] [pid 2560] [remote 165.84.106.3:54656] Not Found: /images/logo.jpg
[Thu Jul 09 01:11:24.411438 2020] [wsgi:error] [pid 2560] [remote 165.84.106.3:54656] Not Found: /show/
[Thu Jul 09 01:11:29.838818 2020] [wsgi:error] [pid 2560] [remote 165.84.106.3:54657] Not Found: /images/logo.jpg
[Thu Jul 09 01:11:29.888043 2020] [wsgi:error] [pid 2560] [remote 165.84.106.3:54657] Not Found: /images/welcome-image.jpg
[Thu Jul 09 01:11:39.276619 2020] [wsgi:error] [pid 2560] [remote 165.84.106.3:54658] Not Found: /show/
[Thu Jul 09 01:11:40.551945 2020] [wsgi:error] [pid 2560] [remote 165.84.106.3:54658] Not Found: /show/
[Thu Jul 09 01:11:41.514498 2020] [wsgi:error] [pid 2560] [remote 165.84.106.3:54658] Not Found: /images/logo.jpg
[Thu Jul 09 01:11:41.563876 2020] [wsgi:error] [pid 2560] [remote 165.84.106.3:54658] Not Found: /images/welcome-image.jpg
[Thu Jul 09 01:11:44.090515 2020] [wsgi:error] [pid 2560] [remote 165.84.106.3:54658] Not Found: /images/logo.jpg
[Thu Jul 09 01:11:44.090698 2020] [wsgi:error] [pid 2560] [remote 165.84.106.3:54660] Not Found: /images/welcome-image.jpg
[Thu Jul 09 01:11:57.685700 2020] [wsgi:error] [pid 2560] [remote 165.84.106.3:54661] Not Found: /
[Thu Jul 09 01:13:20.457680 2020] [wsgi:error] [pid 2560] [remote 165.84.106.3:54708] Not Found: /images/logo.jpg
[Thu Jul 09 01:13:20.460752 2020] [wsgi:error] [pid 2560] [remote 165.84.106.3:54707] Not Found: /images/welcome-image.jpg
[Thu Jul 09 01:13:21.669158 2020] [wsgi:error] [pid 2560] [remote 165.84.106.3:54708] Not Found: /images/welcome-image.jpg
[Thu Jul 09 01:13:21.671665 2020] [wsgi:error] [pid 2560] [remote 165.84.106.3:54707] Not Found: /images/logo.jpg
[Thu Jul 09 01:13:23.866716 2020] [wsgi:error] [pid 2560] [remote 165.84.106.3:54707] Not Found: /
[Thu Jul 09 01:14:33.699125 2020] [wsgi:error] [pid 2560] [remote 165.84.106.3:54712] Not Found: /
[Thu Jul 09 01:15:21.720554 2020] [wsgi:error] [pid 2560] [remote 165.84.106.3:54752] Not Found: /
[Thu Jul 09 01:15:29.384917 2020] [wsgi:error] [pid 2560] [remote 165.84.106.3:54753] Not Found: /
[Thu Jul 09 01:15:30.681508 2020] [wsgi:error] [pid 2560] [remote 165.84.106.3:54754] Not Found: /images/logo.jpg
[Thu Jul 09 01:15:30.681687 2020] [wsgi:error] [pid 2560] [remote 165.84.106.3:54753] Not Found: /images/welcome-image.jpg
[Thu Jul 09 01:15:31.774018 2020] [wsgi:error] [pid 2560] [remote 165.84.106.3:54753] Not Found: /
[Thu Jul 09 01:15:32.726759 2020] [wsgi:error] [pid 2560] [remote 165.84.106.3:54753] Not Found: /images/logo.jpg
[Thu Jul 09 01:15:32.727351 2020] [wsgi:error] [pid 2560] [remote 165.84.106.3:54754] Not Found: /images/welcome-image.jpg
[Thu Jul 09 01:15:57.877671 2020] [wsgi:error] [pid 2560] [remote 165.84.106.3:54756] Not Found: /images/logo.jpg
[Thu Jul 09 01:15:57.928416 2020] [wsgi:error] [pid 2560] [remote 165.84.106.3:54756] Not Found: /images/welcome-image.jpg
[Thu Jul 09 01:16:01.036154 2020] [wsgi:error] [pid 2560] [remote 165.84.106.3:54756] Not Found: /
Exception ignored in: <bound method BaseEventLoop.__del__ of <_UnixSelectorEventLoop running=False closed=False debug=False>>
Traceback (most recent call last):
  File "/usr/lib/python3.6/asyncio/base_events.py", line 526, in __del__
NameError: name 'ResourceWarning' is not defined
[Thu Jul 09 01:16:22.491388 2020] [wsgi:error] [pid 2621] [remote 165.84.106.3:54758] Not Found: /
[Thu Jul 09 01:16:33.503713 2020] [wsgi:error] [pid 2621] [remote 165.84.106.3:54761] Not Found: /images/logo.jpg
[Thu Jul 09 01:16:33.507141 2020] [wsgi:error] [pid 2621] [remote 165.84.106.3:54760] Not Found: /images/welcome-image.jpg
[Thu Jul 09 01:16:38.013578 2020] [wsgi:error] [pid 2621] [remote 165.84.106.3:54760] Not Found: /
[Thu Jul 09 01:16:53.553380 2020] [wsgi:error] [pid 2621] [remote 165.84.106.3:54763] Not Found: /
Exception ignored in: <bound method BaseEventLoop.__del__ of <_UnixSelectorEventLoop running=False closed=False debug=False>>
Traceback (most recent call last):
  File "/usr/lib/python3.6/asyncio/base_events.py", line 526, in __del__
NameError: name 'ResourceWarning' is not defined
[Thu Jul 09 01:17:06.888817 2020] [wsgi:error] [pid 2659] [remote 165.84.106.3:54766] Not Found: /images/welcome-image.jpg
[Thu Jul 09 01:17:06.890592 2020] [wsgi:error] [pid 2659] [remote 165.84.106.3:54767] Not Found: /images/logo.jpg
[Thu Jul 09 01:17:37.720826 2020] [wsgi:error] [pid 2659] [remote 165.84.106.3:54774] Not Found: /images/logo.jpg
[Thu Jul 09 01:17:37.770033 2020] [wsgi:error] [pid 2659] [remote 165.84.106.3:54774] Not Found: /images/welcome-image.jpg
Exception ignored in: <bound method BaseEventLoop.__del__ of <_UnixSelectorEventLoop running=False closed=False debug=False>>
Traceback (most recent call last):
  File "/usr/lib/python3.6/asyncio/base_events.py", line 526, in __del__
NameError: name 'ResourceWarning' is not defined
[Thu Jul 09 01:19:27.443702 2020] [wsgi:error] [pid 2706] [remote 165.84.106.3:54793] Not Found: /images/logo.jpg
[Thu Jul 09 01:19:27.490169 2020] [wsgi:error] [pid 2706] [remote 165.84.106.3:54794] Not Found: /images/welcome-image.jpg
[Thu Jul 09 01:19:29.024702 2020] [wsgi:error] [pid 2706] [remote 165.84.106.3:54794] Not Found: /images/logo.jpg
[Thu Jul 09 01:19:29.028160 2020] [wsgi:error] [pid 2706] [remote 165.84.106.3:54793] Not Found: /images/welcome-image.jpg
[Thu Jul 09 01:20:09.021316 2020] [wsgi:error] [pid 2706] [remote 165.84.106.3:54798] Internal Server Error: /emp
[Thu Jul 09 01:20:09.021349 2020] [wsgi:error] [pid 2706] [remote 165.84.106.3:54798] Traceback (most recent call last):
[Thu Jul 09 01:20:09.021355 2020] [wsgi:error] [pid 2706] [remote 165.84.106.3:54798]   File "/var/www/bcde215_assessment/venv/lib/python3.6/site-packages/django/core/handlers/exception.py", line 34, in inner
[Thu Jul 09 01:20:09.021369 2020] [wsgi:error] [pid 2706] [remote 165.84.106.3:54798]     response = get_response(request)
[Thu Jul 09 01:20:09.021373 2020] [wsgi:error] [pid 2706] [remote 165.84.106.3:54798]   File "/var/www/bcde215_assessment/venv/lib/python3.6/site-packages/django/core/handlers/base.py", line 115, in _get_response
[Thu Jul 09 01:20:09.021377 2020] [wsgi:error] [pid 2706] [remote 165.84.106.3:54798]     response = self.process_exception_by_middleware(e, request)
[Thu Jul 09 01:20:09.021381 2020] [wsgi:error] [pid 2706] [remote 165.84.106.3:54798]   File "/var/www/bcde215_assessment/venv/lib/python3.6/site-packages/django/core/handlers/base.py", line 113, in _get_response
[Thu Jul 09 01:20:09.021385 2020] [wsgi:error] [pid 2706] [remote 165.84.106.3:54798]     response = wrapped_callback(request, *callback_args, **callback_kwargs)
[Thu Jul 09 01:20:09.021389 2020] [wsgi:error] [pid 2706] [remote 165.84.106.3:54798]   File "/var/www/bcde215_assessment/django/nzhealth/covid_cms/views.py", line 17, in emp
[Thu Jul 09 01:20:09.021393 2020] [wsgi:error] [pid 2706] [remote 165.84.106.3:54798]     return render(request,'emp.html',{'form':form})
[Thu Jul 09 01:20:09.021397 2020] [wsgi:error] [pid 2706] [remote 165.84.106.3:54798]   File "/var/www/bcde215_assessment/venv/lib/python3.6/site-packages/django/shortcuts.py", line 19, in render
[Thu Jul 09 01:20:09.021401 2020] [wsgi:error] [pid 2706] [remote 165.84.106.3:54798]     content = loader.render_to_string(template_name, context, request, using=using)
[Thu Jul 09 01:20:09.021405 2020] [wsgi:error] [pid 2706] [remote 165.84.106.3:54798]   File "/var/www/bcde215_assessment/venv/lib/python3.6/site-packages/django/template/loader.py", line 61, in render_to_string
[Thu Jul 09 01:20:09.021408 2020] [wsgi:error] [pid 2706] [remote 165.84.106.3:54798]     template = get_template(template_name, using=using)
[Thu Jul 09 01:20:09.021412 2020] [wsgi:error] [pid 2706] [remote 165.84.106.3:54798]   File "/var/www/bcde215_assessment/venv/lib/python3.6/site-packages/django/template/loader.py", line 19, in get_template
[Thu Jul 09 01:20:09.021428 2020] [wsgi:error] [pid 2706] [remote 165.84.106.3:54798]     raise TemplateDoesNotExist(template_name, chain=chain)
[Thu Jul 09 01:20:09.021433 2020] [wsgi:error] [pid 2706] [remote 165.84.106.3:54798] django.template.exceptions.TemplateDoesNotExist: emp.html
[Thu Jul 09 01:20:09.021439 2020] [wsgi:error] [pid 2706] [remote 165.84.106.3:54798] 
Exception ignored in: <bound method BaseEventLoop.__del__ of <_UnixSelectorEventLoop running=False closed=False debug=False>>
Traceback (most recent call last):
  File "/usr/lib/python3.6/asyncio/base_events.py", line 526, in __del__
NameError: name 'ResourceWarning' is not defined
[Thu Jul 09 01:30:23.288411 2020] [wsgi:error] [pid 2758] [remote 165.84.106.3:55087] Not Found: /images/logo.jpg
[Thu Jul 09 01:30:23.294270 2020] [wsgi:error] [pid 2758] [remote 165.84.106.3:55081] Not Found: /images/welcome-image.jpg
[Thu Jul 09 01:32:23.062632 2020] [wsgi:error] [pid 2758] [remote 165.84.106.3:55108] Internal Server Error: /edit/1
[Thu Jul 09 01:32:23.062665 2020] [wsgi:error] [pid 2758] [remote 165.84.106.3:55108] Traceback (most recent call last):
[Thu Jul 09 01:32:23.062670 2020] [wsgi:error] [pid 2758] [remote 165.84.106.3:55108]   File "/var/www/bcde215_assessment/venv/lib/python3.6/site-packages/django/core/handlers/exception.py", line 34, in inner
[Thu Jul 09 01:32:23.062675 2020] [wsgi:error] [pid 2758] [remote 165.84.106.3:55108]     response = get_response(request)
[Thu Jul 09 01:32:23.062679 2020] [wsgi:error] [pid 2758] [remote 165.84.106.3:55108]   File "/var/www/bcde215_assessment/venv/lib/python3.6/site-packages/django/core/handlers/base.py", line 115, in _get_response
[Thu Jul 09 01:32:23.062683 2020] [wsgi:error] [pid 2758] [remote 165.84.106.3:55108]     response = self.process_exception_by_middleware(e, request)
[Thu Jul 09 01:32:23.062688 2020] [wsgi:error] [pid 2758] [remote 165.84.106.3:55108]   File "/var/www/bcde215_assessment/venv/lib/python3.6/site-packages/django/core/handlers/base.py", line 113, in _get_response
[Thu Jul 09 01:32:23.062701 2020] [wsgi:error] [pid 2758] [remote 165.84.106.3:55108]     response = wrapped_callback(request, *callback_args, **callback_kwargs)
[Thu Jul 09 01:32:23.062706 2020] [wsgi:error] [pid 2758] [remote 165.84.106.3:55108]   File "/var/www/bcde215_assessment/django/nzhealth/covid_cms/views.py", line 23, in edit
[Thu Jul 09 01:32:23.062709 2020] [wsgi:error] [pid 2758] [remote 165.84.106.3:55108]     return render(request,'edit.html', {'referrals':referrals})
[Thu Jul 09 01:32:23.062714 2020] [wsgi:error] [pid 2758] [remote 165.84.106.3:55108] NameError: name 'referrals' is not defined
[Thu Jul 09 01:32:23.062721 2020] [wsgi:error] [pid 2758] [remote 165.84.106.3:55108] 
[Thu Jul 09 01:32:52.444992 2020] [wsgi:error] [pid 2758] [remote 165.84.106.3:55120] Not Found: /images/logo.jpg
[Thu Jul 09 01:32:52.445466 2020] [wsgi:error] [pid 2758] [remote 165.84.106.3:55119] Not Found: /images/welcome-image.jpg
[Thu Jul 09 01:32:55.648383 2020] [wsgi:error] [pid 2758] [remote 165.84.106.3:55119] Not Found: /images/logo.jpg
[Thu Jul 09 01:32:55.651570 2020] [wsgi:error] [pid 2758] [remote 165.84.106.3:55120] Not Found: /images/welcome-image.jpg
[Thu Jul 09 01:35:41.195214 2020] [wsgi:error] [pid 2758] [remote 165.84.106.3:55159] Not Found: /images/logo.jpg
[Thu Jul 09 01:35:41.199947 2020] [wsgi:error] [pid 2758] [remote 165.84.106.3:55158] Not Found: /images/welcome-image.jpg
[Thu Jul 09 01:45:50.146129 2020] [wsgi:error] [pid 2758] [remote 165.84.106.3:55254] Internal Server Error: /
[Thu Jul 09 01:45:50.146165 2020] [wsgi:error] [pid 2758] [remote 165.84.106.3:55254] Traceback (most recent call last):
[Thu Jul 09 01:45:50.146171 2020] [wsgi:error] [pid 2758] [remote 165.84.106.3:55254]   File "/var/www/bcde215_assessment/venv/lib/python3.6/site-packages/django/template/base.py", line 469, in parse
[Thu Jul 09 01:45:50.146175 2020] [wsgi:error] [pid 2758] [remote 165.84.106.3:55254]     compile_func = self.tags[command]
[Thu Jul 09 01:45:50.146179 2020] [wsgi:error] [pid 2758] [remote 165.84.106.3:55254] KeyError: 'latest_news.html'
[Thu Jul 09 01:45:50.146183 2020] [wsgi:error] [pid 2758] [remote 165.84.106.3:55254] 
[Thu Jul 09 01:45:50.146188 2020] [wsgi:error] [pid 2758] [remote 165.84.106.3:55254] During handling of the above exception, another exception occurred:
[Thu Jul 09 01:45:50.146192 2020] [wsgi:error] [pid 2758] [remote 165.84.106.3:55254] 
[Thu Jul 09 01:45:50.146196 2020] [wsgi:error] [pid 2758] [remote 165.84.106.3:55254] Traceback (most recent call last):
[Thu Jul 09 01:45:50.146200 2020] [wsgi:error] [pid 2758] [remote 165.84.106.3:55254]   File "/var/www/bcde215_assessment/venv/lib/python3.6/site-packages/django/core/handlers/exception.py", line 34, in inner
[Thu Jul 09 01:45:50.146204 2020] [wsgi:error] [pid 2758] [remote 165.84.106.3:55254]     response = get_response(request)
[Thu Jul 09 01:45:50.146208 2020] [wsgi:error] [pid 2758] [remote 165.84.106.3:55254]   File "/var/www/bcde215_assessment/venv/lib/python3.6/site-packages/django/core/handlers/base.py", line 115, in _get_response
[Thu Jul 09 01:45:50.146212 2020] [wsgi:error] [pid 2758] [remote 165.84.106.3:55254]     response = self.process_exception_by_middleware(e, request)
[Thu Jul 09 01:45:50.146216 2020] [wsgi:error] [pid 2758] [remote 165.84.106.3:55254]   File "/var/www/bcde215_assessment/venv/lib/python3.6/site-packages/django/core/handlers/base.py", line 113, in _get_response
[Thu Jul 09 01:45:50.146221 2020] [wsgi:error] [pid 2758] [remote 165.84.106.3:55254]     response = wrapped_callback(request, *callback_args, **callback_kwargs)
[Thu Jul 09 01:45:50.146225 2020] [wsgi:error] [pid 2758] [remote 165.84.106.3:55254]   File "/var/www/bcde215_assessment/django/nzhealth/covid_cms/views.py", line 5, in index
[Thu Jul 09 01:45:50.146230 2020] [wsgi:error] [pid 2758] [remote 165.84.106.3:55254]     return render(request, 'index.html', {})
[Thu Jul 09 01:45:50.146242 2020] [wsgi:error] [pid 2758] [remote 165.84.106.3:55254]   File "/var/www/bcde215_assessment/venv/lib/python3.6/site-packages/django/shortcuts.py", line 19, in render
[Thu Jul 09 01:45:50.146246 2020] [wsgi:error] [pid 2758] [remote 165.84.106.3:55254]     content = loader.render_to_string(template_name, context, request, using=using)
[Thu Jul 09 01:45:50.146250 2020] [wsgi:error] [pid 2758] [remote 165.84.106.3:55254]   File "/var/www/bcde215_assessment/venv/lib/python3.6/site-packages/django/template/loader.py", line 61, in render_to_string
[Thu Jul 09 01:45:50.146254 2020] [wsgi:error] [pid 2758] [remote 165.84.106.3:55254]     template = get_template(template_name, using=using)
[Thu Jul 09 01:45:50.146257 2020] [wsgi:error] [pid 2758] [remote 165.84.106.3:55254]   File "/var/www/bcde215_assessment/venv/lib/python3.6/site-packages/django/template/loader.py", line 15, in get_template
[Thu Jul 09 01:45:50.146261 2020] [wsgi:error] [pid 2758] [remote 165.84.106.3:55254]     return engine.get_template(template_name)
[Thu Jul 09 01:45:50.146265 2020] [wsgi:error] [pid 2758] [remote 165.84.106.3:55254]   File "/var/www/bcde215_assessment/venv/lib/python3.6/site-packages/django/template/backends/django.py", line 34, in get_template
[Thu Jul 09 01:45:50.146268 2020] [wsgi:error] [pid 2758] [remote 165.84.106.3:55254]     return Template(self.engine.get_template(template_name), self)
[Thu Jul 09 01:45:50.146272 2020] [wsgi:error] [pid 2758] [remote 165.84.106.3:55254]   File "/var/www/bcde215_assessment/venv/lib/python3.6/site-packages/django/template/engine.py", line 143, in get_template
[Thu Jul 09 01:45:50.146276 2020] [wsgi:error] [pid 2758] [remote 165.84.106.3:55254]     template, origin = self.find_template(template_name)
[Thu Jul 09 01:45:50.146279 2020] [wsgi:error] [pid 2758] [remote 165.84.106.3:55254]   File "/var/www/bcde215_assessment/venv/lib/python3.6/site-packages/django/template/engine.py", line 125, in find_template
[Thu Jul 09 01:45:50.146283 2020] [wsgi:error] [pid 2758] [remote 165.84.106.3:55254]     template = loader.get_template(name, skip=skip)
[Thu Jul 09 01:45:50.146287 2020] [wsgi:error] [pid 2758] [remote 165.84.106.3:55254]   File "/var/www/bcde215_assessment/venv/lib/python3.6/site-packages/django/template/loaders/base.py", line 30, in get_template
[Thu Jul 09 01:45:50.146291 2020] [wsgi:error] [pid 2758] [remote 165.84.106.3:55254]     contents, origin, origin.template_name, self.engine,
[Thu Jul 09 01:45:50.146294 2020] [wsgi:error] [pid 2758] [remote 165.84.106.3:55254]   File "/var/www/bcde215_assessment/venv/lib/python3.6/site-packages/django/template/base.py", line 156, in __init__
[Thu Jul 09 01:45:50.146298 2020] [wsgi:error] [pid 2758] [remote 165.84.106.3:55254]     self.nodelist = self.compile_nodelist()
[Thu Jul 09 01:45:50.146302 2020] [wsgi:error] [pid 2758] [remote 165.84.106.3:55254]   File "/var/www/bcde215_assessment/venv/lib/python3.6/site-packages/django/template/base.py", line 194, in compile_nodelist
[Thu Jul 09 01:45:50.146305 2020] [wsgi:error] [pid 2758] [remote 165.84.106.3:55254]     return parser.parse()
[Thu Jul 09 01:45:50.146309 2020] [wsgi:error] [pid 2758] [remote 165.84.106.3:55254]   File "/var/www/bcde215_assessment/venv/lib/python3.6/site-packages/django/template/base.py", line 471, in parse
[Thu Jul 09 01:45:50.146313 2020] [wsgi:error] [pid 2758] [remote 165.84.106.3:55254]     self.invalid_block_tag(token, command, parse_until)
[Thu Jul 09 01:45:50.146316 2020] [wsgi:error] [pid 2758] [remote 165.84.106.3:55254]   File "/var/www/bcde215_assessment/venv/lib/python3.6/site-packages/django/template/base.py", line 533, in invalid_block_tag
[Thu Jul 09 01:45:50.146320 2020] [wsgi:error] [pid 2758] [remote 165.84.106.3:55254]     "or load this tag?" % (token.lineno, command)
[Thu Jul 09 01:45:50.146325 2020] [wsgi:error] [pid 2758] [remote 165.84.106.3:55254] django.template.exceptions.TemplateSyntaxError: Invalid block tag on line 46: 'latest_news.html'. Did you forget to register or load this tag?
[Thu Jul 09 01:45:50.146332 2020] [wsgi:error] [pid 2758] [remote 165.84.106.3:55254] 
[Thu Jul 09 01:46:12.817775 2020] [wsgi:error] [pid 2758] [remote 165.84.106.3:55257] Internal Server Error: /
[Thu Jul 09 01:46:12.817808 2020] [wsgi:error] [pid 2758] [remote 165.84.106.3:55257] Traceback (most recent call last):
[Thu Jul 09 01:46:12.817813 2020] [wsgi:error] [pid 2758] [remote 165.84.106.3:55257]   File "/var/www/bcde215_assessment/venv/lib/python3.6/site-packages/django/template/base.py", line 469, in parse
[Thu Jul 09 01:46:12.817817 2020] [wsgi:error] [pid 2758] [remote 165.84.106.3:55257]     compile_func = self.tags[command]
[Thu Jul 09 01:46:12.817821 2020] [wsgi:error] [pid 2758] [remote 165.84.106.3:55257] KeyError: 'latest_news.html'
[Thu Jul 09 01:46:12.817825 2020] [wsgi:error] [pid 2758] [remote 165.84.106.3:55257] 
[Thu Jul 09 01:46:12.817828 2020] [wsgi:error] [pid 2758] [remote 165.84.106.3:55257] During handling of the above exception, another exception occurred:
[Thu Jul 09 01:46:12.817832 2020] [wsgi:error] [pid 2758] [remote 165.84.106.3:55257] 
[Thu Jul 09 01:46:12.817836 2020] [wsgi:error] [pid 2758] [remote 165.84.106.3:55257] Traceback (most recent call last):
[Thu Jul 09 01:46:12.817840 2020] [wsgi:error] [pid 2758] [remote 165.84.106.3:55257]   File "/var/www/bcde215_assessment/venv/lib/python3.6/site-packages/django/core/handlers/exception.py", line 34, in inner
[Thu Jul 09 01:46:12.817843 2020] [wsgi:error] [pid 2758] [remote 165.84.106.3:55257]     response = get_response(request)
[Thu Jul 09 01:46:12.817847 2020] [wsgi:error] [pid 2758] [remote 165.84.106.3:55257]   File "/var/www/bcde215_assessment/venv/lib/python3.6/site-packages/django/core/handlers/base.py", line 115, in _get_response
[Thu Jul 09 01:46:12.817851 2020] [wsgi:error] [pid 2758] [remote 165.84.106.3:55257]     response = self.process_exception_by_middleware(e, request)
[Thu Jul 09 01:46:12.817855 2020] [wsgi:error] [pid 2758] [remote 165.84.106.3:55257]   File "/var/www/bcde215_assessment/venv/lib/python3.6/site-packages/django/core/handlers/base.py", line 113, in _get_response
[Thu Jul 09 01:46:12.817859 2020] [wsgi:error] [pid 2758] [remote 165.84.106.3:55257]     response = wrapped_callback(request, *callback_args, **callback_kwargs)
[Thu Jul 09 01:46:12.817863 2020] [wsgi:error] [pid 2758] [remote 165.84.106.3:55257]   File "/var/www/bcde215_assessment/django/nzhealth/covid_cms/views.py", line 5, in index
[Thu Jul 09 01:46:12.817867 2020] [wsgi:error] [pid 2758] [remote 165.84.106.3:55257]     return render(request, 'index.html', {})
[Thu Jul 09 01:46:12.817870 2020] [wsgi:error] [pid 2758] [remote 165.84.106.3:55257]   File "/var/www/bcde215_assessment/venv/lib/python3.6/site-packages/django/shortcuts.py", line 19, in render
[Thu Jul 09 01:46:12.817874 2020] [wsgi:error] [pid 2758] [remote 165.84.106.3:55257]     content = loader.render_to_string(template_name, context, request, using=using)
[Thu Jul 09 01:46:12.817878 2020] [wsgi:error] [pid 2758] [remote 165.84.106.3:55257]   File "/var/www/bcde215_assessment/venv/lib/python3.6/site-packages/django/template/loader.py", line 61, in render_to_string
[Thu Jul 09 01:46:12.817881 2020] [wsgi:error] [pid 2758] [remote 165.84.106.3:55257]     template = get_template(template_name, using=using)
[Thu Jul 09 01:46:12.817885 2020] [wsgi:error] [pid 2758] [remote 165.84.106.3:55257]   File "/var/www/bcde215_assessment/venv/lib/python3.6/site-packages/django/template/loader.py", line 15, in get_template
[Thu Jul 09 01:46:12.817889 2020] [wsgi:error] [pid 2758] [remote 165.84.106.3:55257]     return engine.get_template(template_name)
[Thu Jul 09 01:46:12.817893 2020] [wsgi:error] [pid 2758] [remote 165.84.106.3:55257]   File "/var/www/bcde215_assessment/venv/lib/python3.6/site-packages/django/template/backends/django.py", line 34, in get_template
[Thu Jul 09 01:46:12.817896 2020] [wsgi:error] [pid 2758] [remote 165.84.106.3:55257]     return Template(self.engine.get_template(template_name), self)
[Thu Jul 09 01:46:12.817900 2020] [wsgi:error] [pid 2758] [remote 165.84.106.3:55257]   File "/var/www/bcde215_assessment/venv/lib/python3.6/site-packages/django/template/engine.py", line 143, in get_template
[Thu Jul 09 01:46:12.817914 2020] [wsgi:error] [pid 2758] [remote 165.84.106.3:55257]     template, origin = self.find_template(template_name)
[Thu Jul 09 01:46:12.817918 2020] [wsgi:error] [pid 2758] [remote 165.84.106.3:55257]   File "/var/www/bcde215_assessment/venv/lib/python3.6/site-packages/django/template/engine.py", line 125, in find_template
[Thu Jul 09 01:46:12.817922 2020] [wsgi:error] [pid 2758] [remote 165.84.106.3:55257]     template = loader.get_template(name, skip=skip)
[Thu Jul 09 01:46:12.817926 2020] [wsgi:error] [pid 2758] [remote 165.84.106.3:55257]   File "/var/www/bcde215_assessment/venv/lib/python3.6/site-packages/django/template/loaders/base.py", line 30, in get_template
[Thu Jul 09 01:46:12.817929 2020] [wsgi:error] [pid 2758] [remote 165.84.106.3:55257]     contents, origin, origin.template_name, self.engine,
[Thu Jul 09 01:46:12.817933 2020] [wsgi:error] [pid 2758] [remote 165.84.106.3:55257]   File "/var/www/bcde215_assessment/venv/lib/python3.6/site-packages/django/template/base.py", line 156, in __init__
[Thu Jul 09 01:46:12.817937 2020] [wsgi:error] [pid 2758] [remote 165.84.106.3:55257]     self.nodelist = self.compile_nodelist()
[Thu Jul 09 01:46:12.817941 2020] [wsgi:error] [pid 2758] [remote 165.84.106.3:55257]   File "/var/www/bcde215_assessment/venv/lib/python3.6/site-packages/django/template/base.py", line 194, in compile_nodelist
[Thu Jul 09 01:46:12.817944 2020] [wsgi:error] [pid 2758] [remote 165.84.106.3:55257]     return parser.parse()
[Thu Jul 09 01:46:12.817948 2020] [wsgi:error] [pid 2758] [remote 165.84.106.3:55257]   File "/var/www/bcde215_assessment/venv/lib/python3.6/site-packages/django/template/base.py", line 471, in parse
[Thu Jul 09 01:46:12.817952 2020] [wsgi:error] [pid 2758] [remote 165.84.106.3:55257]     self.invalid_block_tag(token, command, parse_until)
[Thu Jul 09 01:46:12.817955 2020] [wsgi:error] [pid 2758] [remote 165.84.106.3:55257]   File "/var/www/bcde215_assessment/venv/lib/python3.6/site-packages/django/template/base.py", line 533, in invalid_block_tag
[Thu Jul 09 01:46:12.817959 2020] [wsgi:error] [pid 2758] [remote 165.84.106.3:55257]     "or load this tag?" % (token.lineno, command)
[Thu Jul 09 01:46:12.817964 2020] [wsgi:error] [pid 2758] [remote 165.84.106.3:55257] django.template.exceptions.TemplateSyntaxError: Invalid block tag on line 46: 'latest_news.html'. Did you forget to register or load this tag?
[Thu Jul 09 01:46:12.817971 2020] [wsgi:error] [pid 2758] [remote 165.84.106.3:55257] 
[Thu Jul 09 01:50:01.686414 2020] [wsgi:error] [pid 2758] [remote 34.218.50.149:58336] Not Found: /global-protect/msi/GlobalProtect64.msi
[Thu Jul 09 01:56:27.384452 2020] [wsgi:error] [pid 2758] [remote 165.84.106.3:55371] Forbidden (CSRF token missing or incorrect.): /admin/login/
[Thu Jul 09 02:04:47.667621 2020] [wsgi:error] [pid 2758] [remote 44.224.22.196:47905] Not Found: /latest/dynamic/instance-identity/document
[Thu Jul 09 02:04:48.243360 2020] [wsgi:error] [pid 2758] [remote 44.224.22.196:31450] Not Found: /latest/dynamic/instance-identity/document
[Thu Jul 09 02:31:31.066857 2020] [wsgi:error] [pid 2758] [remote 165.84.106.3:56222] Not Found: /index.html
[Thu Jul 09 02:40:10.484972 2020] [wsgi:error] [pid 2758] [remote 37.49.226.35:41442] Not Found: /GponForm/diag_Form
[Thu Jul 09 02:43:21.868861 2020] [wsgi:error] [pid 2758] [remote 165.84.106.3:56680] Not Found: /index.html
[Thu Jul 09 03:33:04.257043 2020] [wsgi:error] [pid 2758] [remote 165.84.106.3:58461] Not Found: /index.html
[Thu Jul 09 03:34:12.424250 2020] [wsgi:error] [pid 2758] [remote 165.84.106.3:58484] Not Found: /index
[Thu Jul 09 03:34:25.624283 2020] [wsgi:error] [pid 2758] [remote 165.84.106.3:58489] Not Found: /index
[Thu Jul 09 04:25:35.345004 2020] [wsgi:error] [pid 2758] [remote 165.84.106.3:59495] Not Found: /index
[Thu Jul 09 04:37:57.436662 2020] [wsgi:error] [pid 2758] [remote 165.84.106.3:59639] Not Found: /index
Exception ignored in: <bound method BaseEventLoop.__del__ of <_UnixSelectorEventLoop running=False closed=False debug=False>>
Traceback (most recent call last):
  File "/usr/lib/python3.6/asyncio/base_events.py", line 526, in __del__
NameError: name 'ResourceWarning' is not defined
[Thu Jul 09 08:07:19.228804 2020] [wsgi:error] [pid 4674] [remote 115.189.100.181:33569] Not Found: /favicon.ico
[Thu Jul 09 08:08:10.253648 2020] [wsgi:error] [pid 4674] [remote 115.189.100.181:33571] Not Found: /favicon.ico
[Thu Jul 09 08:08:48.533924 2020] [wsgi:error] [pid 4674] [remote 115.189.100.181:33551] Not Found: /favicon.ico
[Thu Jul 09 09:31:29.335298 2020] [wsgi:error] [pid 4674] [remote 37.49.226.35:57976] Not Found: /GponForm/diag_Form
[Thu Jul 09 10:59:46.674318 2020] [wsgi:error] [pid 4674] [remote 192.241.215.205:36802] Not Found: /owa/auth/logon.aspx
[Thu Jul 09 12:53:24.636058 2020] [wsgi:error] [pid 4674] [remote 44.225.84.206:25883] Not Found: /latest/dynamic/instance-identity/document
[Thu Jul 09 12:53:25.215338 2020] [wsgi:error] [pid 4674] [remote 44.225.84.206:20135] Not Found: /latest/dynamic/instance-identity/document
[Thu Jul 09 23:06:24.532182 2020] [wsgi:error] [pid 4674] [remote 195.54.160.135:39960] Not Found: /index.php
[Thu Jul 09 23:07:24.760258 2020] [wsgi:error] [pid 4674] [remote 195.54.160.135:37078] Not Found: /api/jsonws/invoke
[Thu Jul 09 23:12:10.694343 2020] [wsgi:error] [pid 4674] [remote 195.54.160.135:35284] Not Found: /vendor/phpunit/phpunit/src/Util/PHP/eval-stdin.php
[Thu Jul 09 23:12:11.995180 2020] [wsgi:error] [pid 4674] [remote 195.54.160.135:34416] Not Found: /vendor/phpunit/phpunit/src/Util/PHP/eval-stdin.php
[Fri Jul 10 00:56:24.999874 2020] [wsgi:error] [pid 4674] [remote 165.84.106.3:61254] Not Found: /favicon.ico
[Fri Jul 10 00:56:33.137874 2020] [wsgi:error] [pid 4674] [remote 165.84.106.3:61254] Internal Server Error: /edit/2
[Fri Jul 10 00:56:33.137907 2020] [wsgi:error] [pid 4674] [remote 165.84.106.3:61254] Traceback (most recent call last):
[Fri Jul 10 00:56:33.137913 2020] [wsgi:error] [pid 4674] [remote 165.84.106.3:61254]   File "/var/www/bcde215_assessment/venv/lib/python3.6/site-packages/django/core/handlers/exception.py", line 34, in inner
[Fri Jul 10 00:56:33.137917 2020] [wsgi:error] [pid 4674] [remote 165.84.106.3:61254]     response = get_response(request)
[Fri Jul 10 00:56:33.137921 2020] [wsgi:error] [pid 4674] [remote 165.84.106.3:61254]   File "/var/www/bcde215_assessment/venv/lib/python3.6/site-packages/django/core/handlers/base.py", line 115, in _get_response
[Fri Jul 10 00:56:33.137926 2020] [wsgi:error] [pid 4674] [remote 165.84.106.3:61254]     response = self.process_exception_by_middleware(e, request)
[Fri Jul 10 00:56:33.137930 2020] [wsgi:error] [pid 4674] [remote 165.84.106.3:61254]   File "/var/www/bcde215_assessment/venv/lib/python3.6/site-packages/django/core/handlers/base.py", line 113, in _get_response
[Fri Jul 10 00:56:33.137935 2020] [wsgi:error] [pid 4674] [remote 165.84.106.3:61254]     response = wrapped_callback(request, *callback_args, **callback_kwargs)
[Fri Jul 10 00:56:33.137939 2020] [wsgi:error] [pid 4674] [remote 165.84.106.3:61254]   File "/var/www/bcde215_assessment/django/nzhealth/covid_cms/views.py", line 23, in edit
[Fri Jul 10 00:56:33.137944 2020] [wsgi:error] [pid 4674] [remote 165.84.106.3:61254]     return render(request,'edit.html', {'referrals':referrals})
[Fri Jul 10 00:56:33.137949 2020] [wsgi:error] [pid 4674] [remote 165.84.106.3:61254] NameError: name 'referrals' is not defined
[Fri Jul 10 00:56:33.137956 2020] [wsgi:error] [pid 4674] [remote 165.84.106.3:61254] 
[Fri Jul 10 00:57:51.192627 2020] [wsgi:error] [pid 4674] [remote 165.84.106.3:61313] Internal Server Error: /edit/4
[Fri Jul 10 00:57:51.192662 2020] [wsgi:error] [pid 4674] [remote 165.84.106.3:61313] Traceback (most recent call last):
[Fri Jul 10 00:57:51.192667 2020] [wsgi:error] [pid 4674] [remote 165.84.106.3:61313]   File "/var/www/bcde215_assessment/venv/lib/python3.6/site-packages/django/core/handlers/exception.py", line 34, in inner
[Fri Jul 10 00:57:51.192672 2020] [wsgi:error] [pid 4674] [remote 165.84.106.3:61313]     response = get_response(request)
[Fri Jul 10 00:57:51.192684 2020] [wsgi:error] [pid 4674] [remote 165.84.106.3:61313]   File "/var/www/bcde215_assessment/venv/lib/python3.6/site-packages/django/core/handlers/base.py", line 115, in _get_response
[Fri Jul 10 00:57:51.192688 2020] [wsgi:error] [pid 4674] [remote 165.84.106.3:61313]     response = self.process_exception_by_middleware(e, request)
[Fri Jul 10 00:57:51.192692 2020] [wsgi:error] [pid 4674] [remote 165.84.106.3:61313]   File "/var/www/bcde215_assessment/venv/lib/python3.6/site-packages/django/core/handlers/base.py", line 113, in _get_response
[Fri Jul 10 00:57:51.192696 2020] [wsgi:error] [pid 4674] [remote 165.84.106.3:61313]     response = wrapped_callback(request, *callback_args, **callback_kwargs)
[Fri Jul 10 00:57:51.192700 2020] [wsgi:error] [pid 4674] [remote 165.84.106.3:61313]   File "/var/www/bcde215_assessment/django/nzhealth/covid_cms/views.py", line 23, in edit
[Fri Jul 10 00:57:51.192703 2020] [wsgi:error] [pid 4674] [remote 165.84.106.3:61313]     return render(request,'edit.html', {'referrals':referrals})
[Fri Jul 10 00:57:51.192708 2020] [wsgi:error] [pid 4674] [remote 165.84.106.3:61313] NameError: name 'referrals' is not defined
[Fri Jul 10 00:57:51.192715 2020] [wsgi:error] [pid 4674] [remote 165.84.106.3:61313] 
[Fri Jul 10 01:40:31.302847 2020] [wsgi:error] [pid 4674] [remote 44.225.84.206:35872] Not Found: /latest/dynamic/instance-identity/document
[Fri Jul 10 01:40:31.884282 2020] [wsgi:error] [pid 4674] [remote 44.225.84.206:14973] Not Found: /latest/dynamic/instance-identity/document
[Fri Jul 10 05:36:40.790987 2020] [wsgi:error] [pid 4674] [remote 128.14.209.178:49048] Not Found: /webfig/
Exception ignored in: <bound method BaseEventLoop.__del__ of <_UnixSelectorEventLoop running=False closed=False debug=False>>
Traceback (most recent call last):
  File "/usr/lib/python3.6/asyncio/base_events.py", line 526, in __del__
NameError: name 'ResourceWarning' is not defined
[Fri Jul 10 13:23:42.380138 2020] [wsgi:error] [pid 11574] [remote 192.241.237.239:56956] Not Found: /owa/auth/logon.aspx
[Fri Jul 10 13:32:06.909772 2020] [wsgi:error] [pid 11574] [remote 44.224.22.196:22657] Not Found: /latest/dynamic/instance-identity/document
[Fri Jul 10 13:32:07.485516 2020] [wsgi:error] [pid 11574] [remote 44.224.22.196:35263] Not Found: /latest/dynamic/instance-identity/document
[Fri Jul 10 14:15:25.066858 2020] [wsgi:error] [pid 11579] [client 176.58.124.134:43820] mod_wsgi (pid=11579): Request data read error when proxying data to daemon process: Internal error (specific information not available).
[Fri Jul 10 14:15:25.067761 2020] [wsgi:error] [pid 11574] [remote 176.58.124.134:43820] Not Found: /msdn.cpp
[Fri Jul 10 14:20:47.755575 2020] [wsgi:error] [pid 11574] [remote 128.14.209.234:43676] Not Found: /webfig/
[Sat Jul 11 01:02:25.915143 2020] [wsgi:error] [pid 11574] [remote 44.224.22.196:30537] Not Found: /latest/dynamic/instance-identity/document
[Sat Jul 11 01:02:26.496517 2020] [wsgi:error] [pid 11574] [remote 44.224.22.196:33815] Not Found: /latest/dynamic/instance-identity/document
[Sat Jul 11 04:28:16.046707 2020] [wsgi:error] [pid 11574] [remote 45.95.168.133:48380] Not Found: /GponForm/diag_Form
Exception ignored in: <bound method BaseEventLoop.__del__ of <_UnixSelectorEventLoop running=False closed=False debug=False>>
Traceback (most recent call last):
  File "/usr/lib/python3.6/asyncio/base_events.py", line 526, in __del__
NameError: name 'ResourceWarning' is not defined
[Sat Jul 11 10:07:27.835956 2020] [wsgi:error] [pid 20733] [remote 45.143.220.115:36274] Not Found: /a2billing/customer/templates/default/footer.tpl
[Sat Jul 11 12:48:18.015707 2020] [wsgi:error] [pid 20733] [remote 44.224.22.196:38021] Not Found: /latest/dynamic/instance-identity/document
[Sat Jul 11 12:48:18.591986 2020] [wsgi:error] [pid 20733] [remote 44.224.22.196:48030] Not Found: /latest/dynamic/instance-identity/document
[Sat Jul 11 13:28:28.550422 2020] [wsgi:error] [pid 20733] [remote 195.54.160.135:52300] Not Found: /index.php
[Sat Jul 11 13:34:30.766877 2020] [wsgi:error] [pid 20733] [remote 195.54.160.135:42894] Not Found: /api/jsonws/invoke
[Sat Jul 11 13:36:03.411138 2020] [wsgi:error] [pid 20733] [remote 80.93.187.123:28918] Not Found: /dump.sql
[Sat Jul 11 13:49:33.774252 2020] [wsgi:error] [pid 20733] [remote 192.241.235.138:43944] Not Found: /owa/auth/logon.aspx
[Sat Jul 11 14:22:01.527642 2020] [wsgi:error] [pid 20733] [remote 195.54.160.135:33978] Not Found: /vendor/phpunit/phpunit/src/Util/PHP/eval-stdin.php
[Sat Jul 11 14:22:01.744397 2020] [wsgi:error] [pid 20733] [remote 195.54.160.135:37910] Not Found: /vendor/phpunit/phpunit/src/Util/PHP/eval-stdin.php
[Sat Jul 11 14:45:32.939299 2020] [wsgi:error] [pid 20733] [remote 77.247.110.28:36132] Not Found: /a2billing/customer/templates/default/footer.tpl
[Sat Jul 11 18:59:22.685436 2020] [wsgi:error] [pid 20733] [remote 45.95.168.133:53684] Not Found: /GponForm/diag_Form
[Sun Jul 12 00:39:31.550041 2020] [wsgi:error] [pid 20733] [remote 44.225.84.206:55626] Not Found: /latest/dynamic/instance-identity/document
[Sun Jul 12 00:39:32.126514 2020] [wsgi:error] [pid 20733] [remote 44.225.84.206:22344] Not Found: /latest/dynamic/instance-identity/document
[Sun Jul 12 04:40:33.068229 2020] [core:error] [pid 20734] [client 195.54.160.115:60764] AH00126: Invalid URI in request GET /dana-na/../dana/html5acc/guacamole/../../../../../../etc/passwd?/dana/html5acc/guacamole/ HTTP/1.1
Exception ignored in: <bound method BaseEventLoop.__del__ of <_UnixSelectorEventLoop running=False closed=False debug=False>>
Traceback (most recent call last):
  File "/usr/lib/python3.6/asyncio/base_events.py", line 526, in __del__
NameError: name 'ResourceWarning' is not defined
[Sun Jul 12 12:26:28.873976 2020] [wsgi:error] [pid 27336] [remote 44.225.84.206:46681] Not Found: /latest/dynamic/instance-identity/document
[Sun Jul 12 12:26:29.451496 2020] [wsgi:error] [pid 27336] [remote 44.225.84.206:21906] Not Found: /latest/dynamic/instance-identity/document
[Sun Jul 12 12:56:33.377207 2020] [wsgi:error] [pid 27336] [remote 45.95.168.133:44000] Not Found: /GponForm/diag_Form
[Sun Jul 12 13:27:08.314260 2020] [wsgi:error] [pid 27336] [remote 47.52.72.22:36236] Not Found: /api/markets/btc_usdt/orderbook
[Sun Jul 12 17:00:07.163825 2020] [wsgi:error] [pid 27336] [remote 192.241.237.71:40552] Not Found: /owa/auth/logon.aspx
[Mon Jul 13 02:02:58.548035 2020] [wsgi:error] [pid 27336] [remote 44.225.84.206:3318] Not Found: /latest/dynamic/instance-identity/document
[Mon Jul 13 02:02:59.129354 2020] [wsgi:error] [pid 27336] [remote 44.225.84.206:52230] Not Found: /latest/dynamic/instance-identity/document
Exception ignored in: <bound method BaseEventLoop.__del__ of <_UnixSelectorEventLoop running=False closed=False debug=False>>
Traceback (most recent call last):
  File "/usr/lib/python3.6/asyncio/base_events.py", line 526, in __del__
NameError: name 'ResourceWarning' is not defined
[Mon Jul 13 13:20:47.316619 2020] [wsgi:error] [pid 1952] [remote 44.224.22.196:62298] Not Found: /latest/dynamic/instance-identity/document
[Mon Jul 13 13:20:47.890641 2020] [wsgi:error] [pid 1952] [remote 44.224.22.196:14208] Not Found: /latest/dynamic/instance-identity/document
[Mon Jul 13 19:15:24.229497 2020] [wsgi:error] [pid 1952] [remote 192.241.227.145:59310] Not Found: /owa/auth/logon.aspx
[Mon Jul 13 22:07:46.497047 2020] [wsgi:error] [pid 1952] [remote 118.93.123.213:49338] Internal Server Error: /edit/4
[Mon Jul 13 22:07:46.497085 2020] [wsgi:error] [pid 1952] [remote 118.93.123.213:49338] Traceback (most recent call last):
[Mon Jul 13 22:07:46.497091 2020] [wsgi:error] [pid 1952] [remote 118.93.123.213:49338]   File "/var/www/bcde215_assessment/venv/lib/python3.6/site-packages/django/core/handlers/exception.py", line 34, in inner
[Mon Jul 13 22:07:46.497096 2020] [wsgi:error] [pid 1952] [remote 118.93.123.213:49338]     response = get_response(request)
[Mon Jul 13 22:07:46.497100 2020] [wsgi:error] [pid 1952] [remote 118.93.123.213:49338]   File "/var/www/bcde215_assessment/venv/lib/python3.6/site-packages/django/core/handlers/base.py", line 115, in _get_response
[Mon Jul 13 22:07:46.497119 2020] [wsgi:error] [pid 1952] [remote 118.93.123.213:49338]     response = self.process_exception_by_middleware(e, request)
[Mon Jul 13 22:07:46.497123 2020] [wsgi:error] [pid 1952] [remote 118.93.123.213:49338]   File "/var/www/bcde215_assessment/venv/lib/python3.6/site-packages/django/core/handlers/base.py", line 113, in _get_response
[Mon Jul 13 22:07:46.497127 2020] [wsgi:error] [pid 1952] [remote 118.93.123.213:49338]     response = wrapped_callback(request, *callback_args, **callback_kwargs)
[Mon Jul 13 22:07:46.497131 2020] [wsgi:error] [pid 1952] [remote 118.93.123.213:49338]   File "/var/www/bcde215_assessment/django/nzhealth/covid_cms/views.py", line 23, in edit
[Mon Jul 13 22:07:46.497135 2020] [wsgi:error] [pid 1952] [remote 118.93.123.213:49338]     return render(request,'edit.html', {'referrals':referrals})
[Mon Jul 13 22:07:46.497141 2020] [wsgi:error] [pid 1952] [remote 118.93.123.213:49338] NameError: name 'referrals' is not defined
[Mon Jul 13 22:07:46.497147 2020] [wsgi:error] [pid 1952] [remote 118.93.123.213:49338] 
[Mon Jul 13 22:08:02.135615 2020] [wsgi:error] [pid 1952] [remote 118.93.123.213:49339] Not Found: /ref
[Mon Jul 13 22:52:39.475093 2020] [wsgi:error] [pid 1952] [remote 47.52.72.22:47228] Not Found: /api/v1/aggTrades
[Tue Jul 14 00:48:33.142482 2020] [wsgi:error] [pid 1952] [remote 44.225.84.206:3018] Not Found: /latest/dynamic/instance-identity/document
[Tue Jul 14 00:48:33.722109 2020] [wsgi:error] [pid 1952] [remote 44.225.84.206:59062] Not Found: /latest/dynamic/instance-identity/document
[Tue Jul 14 06:03:15.645834 2020] [wsgi:error] [pid 1952] [remote 122.57.31.34:59664] Not Found: /favicon.ico
Exception ignored in: <bound method BaseEventLoop.__del__ of <_UnixSelectorEventLoop running=False closed=False debug=False>>
Traceback (most recent call last):
  File "/usr/lib/python3.6/asyncio/base_events.py", line 526, in __del__
NameError: name 'ResourceWarning' is not defined
[Tue Jul 14 07:16:40.580644 2020] [wsgi:error] [pid 8194] [remote 195.54.160.21:51978] Not Found: /index.php
[Tue Jul 14 07:32:25.435069 2020] [wsgi:error] [pid 8194] [remote 195.54.160.21:51584] Not Found: /api/jsonws/invoke
[Tue Jul 14 09:22:58.116618 2020] [wsgi:error] [pid 8194] [remote 195.54.160.21:46600] Not Found: /vendor/phpunit/phpunit/src/Util/PHP/eval-stdin.php
[Tue Jul 14 09:22:58.483365 2020] [wsgi:error] [pid 8194] [remote 195.54.160.21:49664] Not Found: /vendor/phpunit/phpunit/src/Util/PHP/eval-stdin.php
[Tue Jul 14 11:48:38.061929 2020] [wsgi:error] [pid 8194] [remote 118.93.123.213:50625] Internal Server Error: /edit/2
[Tue Jul 14 11:48:38.061972 2020] [wsgi:error] [pid 8194] [remote 118.93.123.213:50625] Traceback (most recent call last):
[Tue Jul 14 11:48:38.061977 2020] [wsgi:error] [pid 8194] [remote 118.93.123.213:50625]   File "/var/www/bcde215_assessment/venv/lib/python3.6/site-packages/django/core/handlers/exception.py", line 34, in inner
[Tue Jul 14 11:48:38.061982 2020] [wsgi:error] [pid 8194] [remote 118.93.123.213:50625]     response = get_response(request)
[Tue Jul 14 11:48:38.061986 2020] [wsgi:error] [pid 8194] [remote 118.93.123.213:50625]   File "/var/www/bcde215_assessment/venv/lib/python3.6/site-packages/django/core/handlers/base.py", line 115, in _get_response
[Tue Jul 14 11:48:38.061991 2020] [wsgi:error] [pid 8194] [remote 118.93.123.213:50625]     response = self.process_exception_by_middleware(e, request)
[Tue Jul 14 11:48:38.061995 2020] [wsgi:error] [pid 8194] [remote 118.93.123.213:50625]   File "/var/www/bcde215_assessment/venv/lib/python3.6/site-packages/django/core/handlers/base.py", line 113, in _get_response
[Tue Jul 14 11:48:38.061999 2020] [wsgi:error] [pid 8194] [remote 118.93.123.213:50625]     response = wrapped_callback(request, *callback_args, **callback_kwargs)
[Tue Jul 14 11:48:38.062004 2020] [wsgi:error] [pid 8194] [remote 118.93.123.213:50625]   File "/var/www/bcde215_assessment/django/nzhealth/covid_cms/views.py", line 23, in edit
[Tue Jul 14 11:48:38.062008 2020] [wsgi:error] [pid 8194] [remote 118.93.123.213:50625]     return render(request,'edit.html', {'referrals':referrals})
[Tue Jul 14 11:48:38.062028 2020] [wsgi:error] [pid 8194] [remote 118.93.123.213:50625] NameError: name 'referrals' is not defined
[Tue Jul 14 11:48:38.062035 2020] [wsgi:error] [pid 8194] [remote 118.93.123.213:50625] 
[Tue Jul 14 14:07:21.039642 2020] [wsgi:error] [pid 8194] [remote 44.224.22.196:45723] Not Found: /latest/dynamic/instance-identity/document
[Tue Jul 14 14:07:21.615720 2020] [wsgi:error] [pid 8194] [remote 44.224.22.196:43967] Not Found: /latest/dynamic/instance-identity/document
[Tue Jul 14 15:01:50.041777 2020] [wsgi:error] [pid 8194] [remote 128.14.133.58:56304] Not Found: /cgi-bin/config.exp
[Tue Jul 14 17:41:02.336444 2020] [wsgi:error] [pid 8194] [remote 128.14.209.178:50414] Not Found: /webfig/
[Tue Jul 14 20:06:35.490674 2020] [wsgi:error] [pid 8194] [remote 162.243.129.179:45204] Not Found: /login
[Tue Jul 14 23:38:31.725966 2020] [wsgi:error] [pid 8194] [remote 122.57.31.34:49413] Not Found: /favicon.ico
[Tue Jul 14 23:46:48.329953 2020] [wsgi:error] [pid 8194] [remote 122.57.31.34:49490] Not Found: /login
Exception ignored in: <bound method BaseEventLoop.__del__ of <_UnixSelectorEventLoop running=False closed=False debug=False>>
Traceback (most recent call last):
  File "/usr/lib/python3.6/asyncio/base_events.py", line 526, in __del__
NameError: name 'ResourceWarning' is not defined
[Tue Jul 14 23:47:27.067454 2020] [wsgi:error] [pid 13103] [remote 122.57.31.34:49511] Not Found: /login
[Tue Jul 14 23:47:43.318590 2020] [wsgi:error] [pid 13103] [remote 122.57.31.34:49512] Internal Server Error: /accounts/login/
[Tue Jul 14 23:47:43.318617 2020] [wsgi:error] [pid 13103] [remote 122.57.31.34:49512] Traceback (most recent call last):
[Tue Jul 14 23:47:43.318622 2020] [wsgi:error] [pid 13103] [remote 122.57.31.34:49512]   File "/var/www/bcde215_assessment/venv/lib/python3.6/site-packages/django/core/handlers/exception.py", line 34, in inner
[Tue Jul 14 23:47:43.318627 2020] [wsgi:error] [pid 13103] [remote 122.57.31.34:49512]     response = get_response(request)
[Tue Jul 14 23:47:43.318631 2020] [wsgi:error] [pid 13103] [remote 122.57.31.34:49512]   File "/var/www/bcde215_assessment/venv/lib/python3.6/site-packages/django/core/handlers/base.py", line 145, in _get_response
[Tue Jul 14 23:47:43.318636 2020] [wsgi:error] [pid 13103] [remote 122.57.31.34:49512]     response = self.process_exception_by_middleware(e, request)
[Tue Jul 14 23:47:43.318640 2020] [wsgi:error] [pid 13103] [remote 122.57.31.34:49512]   File "/var/www/bcde215_assessment/venv/lib/python3.6/site-packages/django/core/handlers/base.py", line 143, in _get_response
[Tue Jul 14 23:47:43.318644 2020] [wsgi:error] [pid 13103] [remote 122.57.31.34:49512]     response = response.render()
[Tue Jul 14 23:47:43.318649 2020] [wsgi:error] [pid 13103] [remote 122.57.31.34:49512]   File "/var/www/bcde215_assessment/venv/lib/python3.6/site-packages/django/template/response.py", line 105, in render
[Tue Jul 14 23:47:43.318653 2020] [wsgi:error] [pid 13103] [remote 122.57.31.34:49512]     self.content = self.rendered_content
[Tue Jul 14 23:47:43.318657 2020] [wsgi:error] [pid 13103] [remote 122.57.31.34:49512]   File "/var/www/bcde215_assessment/venv/lib/python3.6/site-packages/django/template/response.py", line 81, in rendered_content
[Tue Jul 14 23:47:43.318661 2020] [wsgi:error] [pid 13103] [remote 122.57.31.34:49512]     template = self.resolve_template(self.template_name)
[Tue Jul 14 23:47:43.318665 2020] [wsgi:error] [pid 13103] [remote 122.57.31.34:49512]   File "/var/www/bcde215_assessment/venv/lib/python3.6/site-packages/django/template/response.py", line 63, in resolve_template
[Tue Jul 14 23:47:43.318669 2020] [wsgi:error] [pid 13103] [remote 122.57.31.34:49512]     return select_template(template, using=self.using)
[Tue Jul 14 23:47:43.318673 2020] [wsgi:error] [pid 13103] [remote 122.57.31.34:49512]   File "/var/www/bcde215_assessment/venv/lib/python3.6/site-packages/django/template/loader.py", line 47, in select_template
[Tue Jul 14 23:47:43.318677 2020] [wsgi:error] [pid 13103] [remote 122.57.31.34:49512]     raise TemplateDoesNotExist(', '.join(template_name_list), chain=chain)
[Tue Jul 14 23:47:43.318696 2020] [wsgi:error] [pid 13103] [remote 122.57.31.34:49512] django.template.exceptions.TemplateDoesNotExist: registration/login.html
[Tue Jul 14 23:47:43.318715 2020] [wsgi:error] [pid 13103] [remote 122.57.31.34:49512] 
[Tue Jul 14 23:48:10.867679 2020] [wsgi:error] [pid 13103] [remote 122.57.31.34:49519] Internal Server Error: /accounts/login/
[Tue Jul 14 23:48:10.867720 2020] [wsgi:error] [pid 13103] [remote 122.57.31.34:49519] Traceback (most recent call last):
[Tue Jul 14 23:48:10.867725 2020] [wsgi:error] [pid 13103] [remote 122.57.31.34:49519]   File "/var/www/bcde215_assessment/venv/lib/python3.6/site-packages/django/core/handlers/exception.py", line 34, in inner
[Tue Jul 14 23:48:10.867730 2020] [wsgi:error] [pid 13103] [remote 122.57.31.34:49519]     response = get_response(request)
[Tue Jul 14 23:48:10.867734 2020] [wsgi:error] [pid 13103] [remote 122.57.31.34:49519]   File "/var/www/bcde215_assessment/venv/lib/python3.6/site-packages/django/core/handlers/base.py", line 145, in _get_response
[Tue Jul 14 23:48:10.867739 2020] [wsgi:error] [pid 13103] [remote 122.57.31.34:49519]     response = self.process_exception_by_middleware(e, request)
[Tue Jul 14 23:48:10.867743 2020] [wsgi:error] [pid 13103] [remote 122.57.31.34:49519]   File "/var/www/bcde215_assessment/venv/lib/python3.6/site-packages/django/core/handlers/base.py", line 143, in _get_response
[Tue Jul 14 23:48:10.867747 2020] [wsgi:error] [pid 13103] [remote 122.57.31.34:49519]     response = response.render()
[Tue Jul 14 23:48:10.867751 2020] [wsgi:error] [pid 13103] [remote 122.57.31.34:49519]   File "/var/www/bcde215_assessment/venv/lib/python3.6/site-packages/django/template/response.py", line 105, in render
[Tue Jul 14 23:48:10.867755 2020] [wsgi:error] [pid 13103] [remote 122.57.31.34:49519]     self.content = self.rendered_content
[Tue Jul 14 23:48:10.867759 2020] [wsgi:error] [pid 13103] [remote 122.57.31.34:49519]   File "/var/www/bcde215_assessment/venv/lib/python3.6/site-packages/django/template/response.py", line 81, in rendered_content
[Tue Jul 14 23:48:10.867764 2020] [wsgi:error] [pid 13103] [remote 122.57.31.34:49519]     template = self.resolve_template(self.template_name)
[Tue Jul 14 23:48:10.867768 2020] [wsgi:error] [pid 13103] [remote 122.57.31.34:49519]   File "/var/www/bcde215_assessment/venv/lib/python3.6/site-packages/django/template/response.py", line 63, in resolve_template
[Tue Jul 14 23:48:10.867772 2020] [wsgi:error] [pid 13103] [remote 122.57.31.34:49519]     return select_template(template, using=self.using)
[Tue Jul 14 23:48:10.867776 2020] [wsgi:error] [pid 13103] [remote 122.57.31.34:49519]   File "/var/www/bcde215_assessment/venv/lib/python3.6/site-packages/django/template/loader.py", line 47, in select_template
[Tue Jul 14 23:48:10.867780 2020] [wsgi:error] [pid 13103] [remote 122.57.31.34:49519]     raise TemplateDoesNotExist(', '.join(template_name_list), chain=chain)
[Tue Jul 14 23:48:10.867786 2020] [wsgi:error] [pid 13103] [remote 122.57.31.34:49519] django.template.exceptions.TemplateDoesNotExist: registration/login.html
[Tue Jul 14 23:48:10.867793 2020] [wsgi:error] [pid 13103] [remote 122.57.31.34:49519] 
[Tue Jul 14 23:50:08.382673 2020] [wsgi:error] [pid 13103] [remote 199.249.230.149:48472] Not Found: /latest/meta-data/
[Tue Jul 14 23:51:04.082235 2020] [wsgi:error] [pid 13103] [remote 122.57.31.34:49567] Internal Server Error: /accounts/login/
[Tue Jul 14 23:51:04.082279 2020] [wsgi:error] [pid 13103] [remote 122.57.31.34:49567] Traceback (most recent call last):
[Tue Jul 14 23:51:04.082284 2020] [wsgi:error] [pid 13103] [remote 122.57.31.34:49567]   File "/var/www/bcde215_assessment/venv/lib/python3.6/site-packages/django/core/handlers/exception.py", line 34, in inner
[Tue Jul 14 23:51:04.082289 2020] [wsgi:error] [pid 13103] [remote 122.57.31.34:49567]     response = get_response(request)
[Tue Jul 14 23:51:04.082293 2020] [wsgi:error] [pid 13103] [remote 122.57.31.34:49567]   File "/var/www/bcde215_assessment/venv/lib/python3.6/site-packages/django/core/handlers/base.py", line 145, in _get_response
[Tue Jul 14 23:51:04.082306 2020] [wsgi:error] [pid 13103] [remote 122.57.31.34:49567]     response = self.process_exception_by_middleware(e, request)
[Tue Jul 14 23:51:04.082310 2020] [wsgi:error] [pid 13103] [remote 122.57.31.34:49567]   File "/var/www/bcde215_assessment/venv/lib/python3.6/site-packages/django/core/handlers/base.py", line 143, in _get_response
[Tue Jul 14 23:51:04.082314 2020] [wsgi:error] [pid 13103] [remote 122.57.31.34:49567]     response = response.render()
[Tue Jul 14 23:51:04.082318 2020] [wsgi:error] [pid 13103] [remote 122.57.31.34:49567]   File "/var/www/bcde215_assessment/venv/lib/python3.6/site-packages/django/template/response.py", line 105, in render
[Tue Jul 14 23:51:04.082322 2020] [wsgi:error] [pid 13103] [remote 122.57.31.34:49567]     self.content = self.rendered_content
[Tue Jul 14 23:51:04.082325 2020] [wsgi:error] [pid 13103] [remote 122.57.31.34:49567]   File "/var/www/bcde215_assessment/venv/lib/python3.6/site-packages/django/template/response.py", line 81, in rendered_content
[Tue Jul 14 23:51:04.082329 2020] [wsgi:error] [pid 13103] [remote 122.57.31.34:49567]     template = self.resolve_template(self.template_name)
[Tue Jul 14 23:51:04.082333 2020] [wsgi:error] [pid 13103] [remote 122.57.31.34:49567]   File "/var/www/bcde215_assessment/venv/lib/python3.6/site-packages/django/template/response.py", line 63, in resolve_template
[Tue Jul 14 23:51:04.082336 2020] [wsgi:error] [pid 13103] [remote 122.57.31.34:49567]     return select_template(template, using=self.using)
[Tue Jul 14 23:51:04.082340 2020] [wsgi:error] [pid 13103] [remote 122.57.31.34:49567]   File "/var/www/bcde215_assessment/venv/lib/python3.6/site-packages/django/template/loader.py", line 47, in select_template
[Tue Jul 14 23:51:04.082344 2020] [wsgi:error] [pid 13103] [remote 122.57.31.34:49567]     raise TemplateDoesNotExist(', '.join(template_name_list), chain=chain)
[Tue Jul 14 23:51:04.082349 2020] [wsgi:error] [pid 13103] [remote 122.57.31.34:49567] django.template.exceptions.TemplateDoesNotExist: registration/login.html
[Tue Jul 14 23:51:04.082356 2020] [wsgi:error] [pid 13103] [remote 122.57.31.34:49567] 
Exception ignored in: <bound method BaseEventLoop.__del__ of <_UnixSelectorEventLoop running=False closed=False debug=False>>
Traceback (most recent call last):
  File "/usr/lib/python3.6/asyncio/base_events.py", line 526, in __del__
NameError: name 'ResourceWarning' is not defined
[Tue Jul 14 23:52:22.443393 2020] [wsgi:error] [pid 13186] [remote 122.57.31.34:49587] Internal Server Error: /accounts/login/
[Tue Jul 14 23:52:22.443432 2020] [wsgi:error] [pid 13186] [remote 122.57.31.34:49587] Traceback (most recent call last):
[Tue Jul 14 23:52:22.443437 2020] [wsgi:error] [pid 13186] [remote 122.57.31.34:49587]   File "/var/www/bcde215_assessment/venv/lib/python3.6/site-packages/django/core/handlers/exception.py", line 34, in inner
[Tue Jul 14 23:52:22.443441 2020] [wsgi:error] [pid 13186] [remote 122.57.31.34:49587]     response = get_response(request)
[Tue Jul 14 23:52:22.443445 2020] [wsgi:error] [pid 13186] [remote 122.57.31.34:49587]   File "/var/www/bcde215_assessment/venv/lib/python3.6/site-packages/django/core/handlers/base.py", line 145, in _get_response
[Tue Jul 14 23:52:22.443450 2020] [wsgi:error] [pid 13186] [remote 122.57.31.34:49587]     response = self.process_exception_by_middleware(e, request)
[Tue Jul 14 23:52:22.443454 2020] [wsgi:error] [pid 13186] [remote 122.57.31.34:49587]   File "/var/www/bcde215_assessment/venv/lib/python3.6/site-packages/django/core/handlers/base.py", line 143, in _get_response
[Tue Jul 14 23:52:22.443458 2020] [wsgi:error] [pid 13186] [remote 122.57.31.34:49587]     response = response.render()
[Tue Jul 14 23:52:22.443463 2020] [wsgi:error] [pid 13186] [remote 122.57.31.34:49587]   File "/var/www/bcde215_assessment/venv/lib/python3.6/site-packages/django/template/response.py", line 105, in render
[Tue Jul 14 23:52:22.443467 2020] [wsgi:error] [pid 13186] [remote 122.57.31.34:49587]     self.content = self.rendered_content
[Tue Jul 14 23:52:22.443479 2020] [wsgi:error] [pid 13186] [remote 122.57.31.34:49587]   File "/var/www/bcde215_assessment/venv/lib/python3.6/site-packages/django/template/response.py", line 81, in rendered_content
[Tue Jul 14 23:52:22.443483 2020] [wsgi:error] [pid 13186] [remote 122.57.31.34:49587]     template = self.resolve_template(self.template_name)
[Tue Jul 14 23:52:22.443487 2020] [wsgi:error] [pid 13186] [remote 122.57.31.34:49587]   File "/var/www/bcde215_assessment/venv/lib/python3.6/site-packages/django/template/response.py", line 63, in resolve_template
[Tue Jul 14 23:52:22.443491 2020] [wsgi:error] [pid 13186] [remote 122.57.31.34:49587]     return select_template(template, using=self.using)
[Tue Jul 14 23:52:22.443494 2020] [wsgi:error] [pid 13186] [remote 122.57.31.34:49587]   File "/var/www/bcde215_assessment/venv/lib/python3.6/site-packages/django/template/loader.py", line 47, in select_template
[Tue Jul 14 23:52:22.443498 2020] [wsgi:error] [pid 13186] [remote 122.57.31.34:49587]     raise TemplateDoesNotExist(', '.join(template_name_list), chain=chain)
[Tue Jul 14 23:52:22.443508 2020] [wsgi:error] [pid 13186] [remote 122.57.31.34:49587] django.template.exceptions.TemplateDoesNotExist: registration/login.html
[Tue Jul 14 23:52:22.443515 2020] [wsgi:error] [pid 13186] [remote 122.57.31.34:49587] 
[Wed Jul 15 00:45:36.835314 2020] [wsgi:error] [pid 13186] [remote 122.57.31.34:50290] Internal Server Error: /accounts/login/
[Wed Jul 15 00:45:36.835351 2020] [wsgi:error] [pid 13186] [remote 122.57.31.34:50290] Traceback (most recent call last):
[Wed Jul 15 00:45:36.835357 2020] [wsgi:error] [pid 13186] [remote 122.57.31.34:50290]   File "/var/www/bcde215_assessment/venv/lib/python3.6/site-packages/django/template/backends/django.py", line 61, in render
[Wed Jul 15 00:45:36.835362 2020] [wsgi:error] [pid 13186] [remote 122.57.31.34:50290]     return self.template.render(context)
[Wed Jul 15 00:45:36.835366 2020] [wsgi:error] [pid 13186] [remote 122.57.31.34:50290]   File "/var/www/bcde215_assessment/venv/lib/python3.6/site-packages/django/template/base.py", line 171, in render
[Wed Jul 15 00:45:36.835371 2020] [wsgi:error] [pid 13186] [remote 122.57.31.34:50290]     return self._render(context)
[Wed Jul 15 00:45:36.835375 2020] [wsgi:error] [pid 13186] [remote 122.57.31.34:50290]   File "/var/www/bcde215_assessment/venv/lib/python3.6/site-packages/django/template/base.py", line 163, in _render
[Wed Jul 15 00:45:36.835379 2020] [wsgi:error] [pid 13186] [remote 122.57.31.34:50290]     return self.nodelist.render(context)
[Wed Jul 15 00:45:36.835384 2020] [wsgi:error] [pid 13186] [remote 122.57.31.34:50290]   File "/var/www/bcde215_assessment/venv/lib/python3.6/site-packages/django/template/base.py", line 936, in render
[Wed Jul 15 00:45:36.835388 2020] [wsgi:error] [pid 13186] [remote 122.57.31.34:50290]     bit = node.render_annotated(context)
[Wed Jul 15 00:45:36.835392 2020] [wsgi:error] [pid 13186] [remote 122.57.31.34:50290]   File "/var/www/bcde215_assessment/venv/lib/python3.6/site-packages/django/template/base.py", line 903, in render_annotated
[Wed Jul 15 00:45:36.835396 2020] [wsgi:error] [pid 13186] [remote 122.57.31.34:50290]     return self.render(context)
[Wed Jul 15 00:45:36.835400 2020] [wsgi:error] [pid 13186] [remote 122.57.31.34:50290]   File "/var/www/bcde215_assessment/venv/lib/python3.6/site-packages/django/template/loader_tags.py", line 127, in render
[Wed Jul 15 00:45:36.835405 2020] [wsgi:error] [pid 13186] [remote 122.57.31.34:50290]     compiled_parent = self.get_parent(context)
[Wed Jul 15 00:45:36.835409 2020] [wsgi:error] [pid 13186] [remote 122.57.31.34:50290]   File "/var/www/bcde215_assessment/venv/lib/python3.6/site-packages/django/template/loader_tags.py", line 124, in get_parent
[Wed Jul 15 00:45:36.835413 2020] [wsgi:error] [pid 13186] [remote 122.57.31.34:50290]     return self.find_template(parent, context)
[Wed Jul 15 00:45:36.835417 2020] [wsgi:error] [pid 13186] [remote 122.57.31.34:50290]   File "/var/www/bcde215_assessment/venv/lib/python3.6/site-packages/django/template/loader_tags.py", line 104, in find_template
[Wed Jul 15 00:45:36.835431 2020] [wsgi:error] [pid 13186] [remote 122.57.31.34:50290]     template_name, skip=history,
[Wed Jul 15 00:45:36.835435 2020] [wsgi:error] [pid 13186] [remote 122.57.31.34:50290]   File "/var/www/bcde215_assessment/venv/lib/python3.6/site-packages/django/template/engine.py", line 129, in find_template
[Wed Jul 15 00:45:36.835439 2020] [wsgi:error] [pid 13186] [remote 122.57.31.34:50290]     raise TemplateDoesNotExist(name, tried=tried)
[Wed Jul 15 00:45:36.835442 2020] [wsgi:error] [pid 13186] [remote 122.57.31.34:50290] django.template.exceptions.TemplateDoesNotExist: main.html
[Wed Jul 15 00:45:36.835446 2020] [wsgi:error] [pid 13186] [remote 122.57.31.34:50290] 
[Wed Jul 15 00:45:36.835450 2020] [wsgi:error] [pid 13186] [remote 122.57.31.34:50290] The above exception was the direct cause of the following exception:
[Wed Jul 15 00:45:36.835453 2020] [wsgi:error] [pid 13186] [remote 122.57.31.34:50290] 
[Wed Jul 15 00:45:36.835457 2020] [wsgi:error] [pid 13186] [remote 122.57.31.34:50290] Traceback (most recent call last):
[Wed Jul 15 00:45:36.835460 2020] [wsgi:error] [pid 13186] [remote 122.57.31.34:50290]   File "/var/www/bcde215_assessment/venv/lib/python3.6/site-packages/django/core/handlers/exception.py", line 34, in inner
[Wed Jul 15 00:45:36.835464 2020] [wsgi:error] [pid 13186] [remote 122.57.31.34:50290]     response = get_response(request)
[Wed Jul 15 00:45:36.835468 2020] [wsgi:error] [pid 13186] [remote 122.57.31.34:50290]   File "/var/www/bcde215_assessment/venv/lib/python3.6/site-packages/django/core/handlers/base.py", line 145, in _get_response
[Wed Jul 15 00:45:36.835471 2020] [wsgi:error] [pid 13186] [remote 122.57.31.34:50290]     response = self.process_exception_by_middleware(e, request)
[Wed Jul 15 00:45:36.835475 2020] [wsgi:error] [pid 13186] [remote 122.57.31.34:50290]   File "/var/www/bcde215_assessment/venv/lib/python3.6/site-packages/django/core/handlers/base.py", line 143, in _get_response
[Wed Jul 15 00:45:36.835479 2020] [wsgi:error] [pid 13186] [remote 122.57.31.34:50290]     response = response.render()
[Wed Jul 15 00:45:36.835483 2020] [wsgi:error] [pid 13186] [remote 122.57.31.34:50290]   File "/var/www/bcde215_assessment/venv/lib/python3.6/site-packages/django/template/response.py", line 105, in render
[Wed Jul 15 00:45:36.835486 2020] [wsgi:error] [pid 13186] [remote 122.57.31.34:50290]     self.content = self.rendered_content
[Wed Jul 15 00:45:36.835490 2020] [wsgi:error] [pid 13186] [remote 122.57.31.34:50290]   File "/var/www/bcde215_assessment/venv/lib/python3.6/site-packages/django/template/response.py", line 83, in rendered_content
[Wed Jul 15 00:45:36.835494 2020] [wsgi:error] [pid 13186] [remote 122.57.31.34:50290]     return template.render(context, self._request)
[Wed Jul 15 00:45:36.835497 2020] [wsgi:error] [pid 13186] [remote 122.57.31.34:50290]   File "/var/www/bcde215_assessment/venv/lib/python3.6/site-packages/django/template/backends/django.py", line 63, in render
[Wed Jul 15 00:45:36.835501 2020] [wsgi:error] [pid 13186] [remote 122.57.31.34:50290]     reraise(exc, self.backend)
[Wed Jul 15 00:45:36.835505 2020] [wsgi:error] [pid 13186] [remote 122.57.31.34:50290]   File "/var/www/bcde215_assessment/venv/lib/python3.6/site-packages/django/template/backends/django.py", line 84, in reraise
[Wed Jul 15 00:45:36.835509 2020] [wsgi:error] [pid 13186] [remote 122.57.31.34:50290]     raise new from exc
[Wed Jul 15 00:45:36.835513 2020] [wsgi:error] [pid 13186] [remote 122.57.31.34:50290] django.template.exceptions.TemplateDoesNotExist: main.html
[Wed Jul 15 00:45:36.835521 2020] [wsgi:error] [pid 13186] [remote 122.57.31.34:50290] 
[Wed Jul 15 00:50:19.398404 2020] [wsgi:error] [pid 13186] [remote 122.57.31.34:50361] Internal Server Error: /accounts/login/
[Wed Jul 15 00:50:19.398447 2020] [wsgi:error] [pid 13186] [remote 122.57.31.34:50361] Traceback (most recent call last):
[Wed Jul 15 00:50:19.398452 2020] [wsgi:error] [pid 13186] [remote 122.57.31.34:50361]   File "/var/www/bcde215_assessment/venv/lib/python3.6/site-packages/django/template/backends/django.py", line 61, in render
[Wed Jul 15 00:50:19.398466 2020] [wsgi:error] [pid 13186] [remote 122.57.31.34:50361]     return self.template.render(context)
[Wed Jul 15 00:50:19.398470 2020] [wsgi:error] [pid 13186] [remote 122.57.31.34:50361]   File "/var/www/bcde215_assessment/venv/lib/python3.6/site-packages/django/template/base.py", line 171, in render
[Wed Jul 15 00:50:19.398474 2020] [wsgi:error] [pid 13186] [remote 122.57.31.34:50361]     return self._render(context)
[Wed Jul 15 00:50:19.398478 2020] [wsgi:error] [pid 13186] [remote 122.57.31.34:50361]   File "/var/www/bcde215_assessment/venv/lib/python3.6/site-packages/django/template/base.py", line 163, in _render
[Wed Jul 15 00:50:19.398481 2020] [wsgi:error] [pid 13186] [remote 122.57.31.34:50361]     return self.nodelist.render(context)
[Wed Jul 15 00:50:19.398485 2020] [wsgi:error] [pid 13186] [remote 122.57.31.34:50361]   File "/var/www/bcde215_assessment/venv/lib/python3.6/site-packages/django/template/base.py", line 936, in render
[Wed Jul 15 00:50:19.398489 2020] [wsgi:error] [pid 13186] [remote 122.57.31.34:50361]     bit = node.render_annotated(context)
[Wed Jul 15 00:50:19.398492 2020] [wsgi:error] [pid 13186] [remote 122.57.31.34:50361]   File "/var/www/bcde215_assessment/venv/lib/python3.6/site-packages/django/template/base.py", line 903, in render_annotated
[Wed Jul 15 00:50:19.398496 2020] [wsgi:error] [pid 13186] [remote 122.57.31.34:50361]     return self.render(context)
[Wed Jul 15 00:50:19.398500 2020] [wsgi:error] [pid 13186] [remote 122.57.31.34:50361]   File "/var/www/bcde215_assessment/venv/lib/python3.6/site-packages/django/template/loader_tags.py", line 127, in render
[Wed Jul 15 00:50:19.398503 2020] [wsgi:error] [pid 13186] [remote 122.57.31.34:50361]     compiled_parent = self.get_parent(context)
[Wed Jul 15 00:50:19.398507 2020] [wsgi:error] [pid 13186] [remote 122.57.31.34:50361]   File "/var/www/bcde215_assessment/venv/lib/python3.6/site-packages/django/template/loader_tags.py", line 124, in get_parent
[Wed Jul 15 00:50:19.398511 2020] [wsgi:error] [pid 13186] [remote 122.57.31.34:50361]     return self.find_template(parent, context)
[Wed Jul 15 00:50:19.398514 2020] [wsgi:error] [pid 13186] [remote 122.57.31.34:50361]   File "/var/www/bcde215_assessment/venv/lib/python3.6/site-packages/django/template/loader_tags.py", line 104, in find_template
[Wed Jul 15 00:50:19.398518 2020] [wsgi:error] [pid 13186] [remote 122.57.31.34:50361]     template_name, skip=history,
[Wed Jul 15 00:50:19.398522 2020] [wsgi:error] [pid 13186] [remote 122.57.31.34:50361]   File "/var/www/bcde215_assessment/venv/lib/python3.6/site-packages/django/template/engine.py", line 129, in find_template
[Wed Jul 15 00:50:19.398525 2020] [wsgi:error] [pid 13186] [remote 122.57.31.34:50361]     raise TemplateDoesNotExist(name, tried=tried)
[Wed Jul 15 00:50:19.398529 2020] [wsgi:error] [pid 13186] [remote 122.57.31.34:50361] django.template.exceptions.TemplateDoesNotExist: main.html
[Wed Jul 15 00:50:19.398533 2020] [wsgi:error] [pid 13186] [remote 122.57.31.34:50361] 
[Wed Jul 15 00:50:19.398536 2020] [wsgi:error] [pid 13186] [remote 122.57.31.34:50361] The above exception was the direct cause of the following exception:
[Wed Jul 15 00:50:19.398540 2020] [wsgi:error] [pid 13186] [remote 122.57.31.34:50361] 
[Wed Jul 15 00:50:19.398543 2020] [wsgi:error] [pid 13186] [remote 122.57.31.34:50361] Traceback (most recent call last):
[Wed Jul 15 00:50:19.398547 2020] [wsgi:error] [pid 13186] [remote 122.57.31.34:50361]   File "/var/www/bcde215_assessment/venv/lib/python3.6/site-packages/django/core/handlers/exception.py", line 34, in inner
[Wed Jul 15 00:50:19.398550 2020] [wsgi:error] [pid 13186] [remote 122.57.31.34:50361]     response = get_response(request)
[Wed Jul 15 00:50:19.398554 2020] [wsgi:error] [pid 13186] [remote 122.57.31.34:50361]   File "/var/www/bcde215_assessment/venv/lib/python3.6/site-packages/django/core/handlers/base.py", line 145, in _get_response
[Wed Jul 15 00:50:19.398560 2020] [wsgi:error] [pid 13186] [remote 122.57.31.34:50361]     response = self.process_exception_by_middleware(e, request)
[Wed Jul 15 00:50:19.398564 2020] [wsgi:error] [pid 13186] [remote 122.57.31.34:50361]   File "/var/www/bcde215_assessment/venv/lib/python3.6/site-packages/django/core/handlers/base.py", line 143, in _get_response
[Wed Jul 15 00:50:19.398568 2020] [wsgi:error] [pid 13186] [remote 122.57.31.34:50361]     response = response.render()
[Wed Jul 15 00:50:19.398571 2020] [wsgi:error] [pid 13186] [remote 122.57.31.34:50361]   File "/var/www/bcde215_assessment/venv/lib/python3.6/site-packages/django/template/response.py", line 105, in render
[Wed Jul 15 00:50:19.398575 2020] [wsgi:error] [pid 13186] [remote 122.57.31.34:50361]     self.content = self.rendered_content
[Wed Jul 15 00:50:19.398579 2020] [wsgi:error] [pid 13186] [remote 122.57.31.34:50361]   File "/var/www/bcde215_assessment/venv/lib/python3.6/site-packages/django/template/response.py", line 83, in rendered_content
[Wed Jul 15 00:50:19.398583 2020] [wsgi:error] [pid 13186] [remote 122.57.31.34:50361]     return template.render(context, self._request)
[Wed Jul 15 00:50:19.398586 2020] [wsgi:error] [pid 13186] [remote 122.57.31.34:50361]   File "/var/www/bcde215_assessment/venv/lib/python3.6/site-packages/django/template/backends/django.py", line 63, in render
[Wed Jul 15 00:50:19.398590 2020] [wsgi:error] [pid 13186] [remote 122.57.31.34:50361]     reraise(exc, self.backend)
[Wed Jul 15 00:50:19.398593 2020] [wsgi:error] [pid 13186] [remote 122.57.31.34:50361]   File "/var/www/bcde215_assessment/venv/lib/python3.6/site-packages/django/template/backends/django.py", line 84, in reraise
[Wed Jul 15 00:50:19.398597 2020] [wsgi:error] [pid 13186] [remote 122.57.31.34:50361]     raise new from exc
[Wed Jul 15 00:50:19.398602 2020] [wsgi:error] [pid 13186] [remote 122.57.31.34:50361] django.template.exceptions.TemplateDoesNotExist: main.html
[Wed Jul 15 00:50:19.398609 2020] [wsgi:error] [pid 13186] [remote 122.57.31.34:50361] 
[Wed Jul 15 02:00:13.085922 2020] [wsgi:error] [pid 13186] [remote 44.225.84.206:58872] Not Found: /latest/dynamic/instance-identity/document
[Wed Jul 15 02:00:13.665306 2020] [wsgi:error] [pid 13186] [remote 44.225.84.206:8254] Not Found: /latest/dynamic/instance-identity/document
[Wed Jul 15 03:52:22.174001 2020] [wsgi:error] [pid 13186] [remote 128.14.134.170:59596] Not Found: /Telerik.Web.UI.WebResource.axd
Exception ignored in: <bound method BaseEventLoop.__del__ of <_UnixSelectorEventLoop running=False closed=False debug=False>>
Traceback (most recent call last):
  File "/usr/lib/python3.6/asyncio/base_events.py", line 526, in __del__
NameError: name 'ResourceWarning' is not defined
[Wed Jul 15 12:42:47.221931 2020] [wsgi:error] [pid 15350] [remote 44.225.84.206:53360] Not Found: /latest/dynamic/instance-identity/document
[Wed Jul 15 12:42:47.798574 2020] [wsgi:error] [pid 15350] [remote 44.225.84.206:42644] Not Found: /latest/dynamic/instance-identity/document
Exception ignored in: <bound method BaseEventLoop.__del__ of <_UnixSelectorEventLoop running=False closed=False debug=False>>
Traceback (most recent call last):
  File "/usr/lib/python3.6/asyncio/base_events.py", line 526, in __del__
NameError: name 'ResourceWarning' is not defined
[Wed Jul 15 21:14:50.057862 2020] [wsgi:error] [pid 20066] [remote 122.57.27.245:55054] Not Found: /home
Exception ignored in: <bound method BaseEventLoop.__del__ of <_UnixSelectorEventLoop running=False closed=False debug=False>>
Traceback (most recent call last):
  File "/usr/lib/python3.6/asyncio/base_events.py", line 526, in __del__
NameError: name 'ResourceWarning' is not defined
[Wed Jul 15 21:17:31.641569 2020] [wsgi:error] [pid 20186] [remote 122.57.27.245:55075] Not Found: /accounts/login/home
[Wed Jul 15 21:17:45.185991 2020] [wsgi:error] [pid 20186] [remote 122.57.27.245:55079] Not Found: /accounts/login/home
Exception ignored in: <bound method BaseEventLoop.__del__ of <_UnixSelectorEventLoop running=False closed=False debug=False>>
Traceback (most recent call last):
  File "/usr/lib/python3.6/asyncio/base_events.py", line 526, in __del__
NameError: name 'ResourceWarning' is not defined
[Wed Jul 15 21:20:29.683195 2020] [wsgi:error] [pid 20307] [remote 122.57.27.245:55129] Internal Server Error: /accounts/login/
[Wed Jul 15 21:20:29.683235 2020] [wsgi:error] [pid 20307] [remote 122.57.27.245:55129] Traceback (most recent call last):
[Wed Jul 15 21:20:29.683240 2020] [wsgi:error] [pid 20307] [remote 122.57.27.245:55129]   File "/var/www/bcde215_assessment/venv/lib/python3.6/site-packages/django/core/handlers/exception.py", line 34, in inner
[Wed Jul 15 21:20:29.683244 2020] [wsgi:error] [pid 20307] [remote 122.57.27.245:55129]     response = get_response(request)
[Wed Jul 15 21:20:29.683248 2020] [wsgi:error] [pid 20307] [remote 122.57.27.245:55129]   File "/var/www/bcde215_assessment/venv/lib/python3.6/site-packages/django/core/handlers/base.py", line 100, in _get_response
[Wed Jul 15 21:20:29.683252 2020] [wsgi:error] [pid 20307] [remote 122.57.27.245:55129]     resolver_match = resolver.resolve(request.path_info)
[Wed Jul 15 21:20:29.683256 2020] [wsgi:error] [pid 20307] [remote 122.57.27.245:55129]   File "/var/www/bcde215_assessment/venv/lib/python3.6/site-packages/django/urls/resolvers.py", line 544, in resolve
[Wed Jul 15 21:20:29.683260 2020] [wsgi:error] [pid 20307] [remote 122.57.27.245:55129]     for pattern in self.url_patterns:
[Wed Jul 15 21:20:29.683264 2020] [wsgi:error] [pid 20307] [remote 122.57.27.245:55129]   File "/var/www/bcde215_assessment/venv/lib/python3.6/site-packages/django/utils/functional.py", line 48, in __get__
[Wed Jul 15 21:20:29.683267 2020] [wsgi:error] [pid 20307] [remote 122.57.27.245:55129]     res = instance.__dict__[self.name] = self.func(instance)
[Wed Jul 15 21:20:29.683271 2020] [wsgi:error] [pid 20307] [remote 122.57.27.245:55129]   File "/var/www/bcde215_assessment/venv/lib/python3.6/site-packages/django/urls/resolvers.py", line 588, in url_patterns
[Wed Jul 15 21:20:29.683275 2020] [wsgi:error] [pid 20307] [remote 122.57.27.245:55129]     patterns = getattr(self.urlconf_module, "urlpatterns", self.urlconf_module)
[Wed Jul 15 21:20:29.683278 2020] [wsgi:error] [pid 20307] [remote 122.57.27.245:55129]   File "/var/www/bcde215_assessment/venv/lib/python3.6/site-packages/django/utils/functional.py", line 48, in __get__
[Wed Jul 15 21:20:29.683282 2020] [wsgi:error] [pid 20307] [remote 122.57.27.245:55129]     res = instance.__dict__[self.name] = self.func(instance)
[Wed Jul 15 21:20:29.683286 2020] [wsgi:error] [pid 20307] [remote 122.57.27.245:55129]   File "/var/www/bcde215_assessment/venv/lib/python3.6/site-packages/django/urls/resolvers.py", line 581, in urlconf_module
[Wed Jul 15 21:20:29.683290 2020] [wsgi:error] [pid 20307] [remote 122.57.27.245:55129]     return import_module(self.urlconf_name)
[Wed Jul 15 21:20:29.683293 2020] [wsgi:error] [pid 20307] [remote 122.57.27.245:55129]   File "/usr/lib/python3.6/importlib/__init__.py", line 126, in import_module
[Wed Jul 15 21:20:29.683297 2020] [wsgi:error] [pid 20307] [remote 122.57.27.245:55129]     return _bootstrap._gcd_import(name[level:], package, level)
[Wed Jul 15 21:20:29.683300 2020] [wsgi:error] [pid 20307] [remote 122.57.27.245:55129]   File "<frozen importlib._bootstrap>", line 994, in _gcd_import
[Wed Jul 15 21:20:29.683304 2020] [wsgi:error] [pid 20307] [remote 122.57.27.245:55129]   File "<frozen importlib._bootstrap>", line 971, in _find_and_load
[Wed Jul 15 21:20:29.683307 2020] [wsgi:error] [pid 20307] [remote 122.57.27.245:55129]   File "<frozen importlib._bootstrap>", line 955, in _find_and_load_unlocked
[Wed Jul 15 21:20:29.683311 2020] [wsgi:error] [pid 20307] [remote 122.57.27.245:55129]   File "<frozen importlib._bootstrap>", line 665, in _load_unlocked
[Wed Jul 15 21:20:29.683314 2020] [wsgi:error] [pid 20307] [remote 122.57.27.245:55129]   File "<frozen importlib._bootstrap_external>", line 674, in exec_module
[Wed Jul 15 21:20:29.683318 2020] [wsgi:error] [pid 20307] [remote 122.57.27.245:55129]   File "<frozen importlib._bootstrap_external>", line 781, in get_code
[Wed Jul 15 21:20:29.683330 2020] [wsgi:error] [pid 20307] [remote 122.57.27.245:55129]   File "<frozen importlib._bootstrap_external>", line 741, in source_to_code
[Wed Jul 15 21:20:29.683334 2020] [wsgi:error] [pid 20307] [remote 122.57.27.245:55129]   File "<frozen importlib._bootstrap>", line 219, in _call_with_frames_removed
[Wed Jul 15 21:20:29.683337 2020] [wsgi:error] [pid 20307] [remote 122.57.27.245:55129]   File "/var/www/bcde215_assessment/django/nzhealth/nzhealth/urls.py", line 34
[Wed Jul 15 21:20:29.683341 2020] [wsgi:error] [pid 20307] [remote 122.57.27.245:55129]     ,
[Wed Jul 15 21:20:29.683344 2020] [wsgi:error] [pid 20307] [remote 122.57.27.245:55129]     ^
[Wed Jul 15 21:20:29.683349 2020] [wsgi:error] [pid 20307] [remote 122.57.27.245:55129] SyntaxError: invalid syntax
[Wed Jul 15 21:20:29.683356 2020] [wsgi:error] [pid 20307] [remote 122.57.27.245:55129] 
[Wed Jul 15 21:20:35.163624 2020] [wsgi:error] [pid 20307] [remote 122.57.27.245:55130] Internal Server Error: /
[Wed Jul 15 21:20:35.163657 2020] [wsgi:error] [pid 20307] [remote 122.57.27.245:55130] Traceback (most recent call last):
[Wed Jul 15 21:20:35.163661 2020] [wsgi:error] [pid 20307] [remote 122.57.27.245:55130]   File "/var/www/bcde215_assessment/venv/lib/python3.6/site-packages/django/core/handlers/exception.py", line 34, in inner
[Wed Jul 15 21:20:35.163666 2020] [wsgi:error] [pid 20307] [remote 122.57.27.245:55130]     response = get_response(request)
[Wed Jul 15 21:20:35.163670 2020] [wsgi:error] [pid 20307] [remote 122.57.27.245:55130]   File "/var/www/bcde215_assessment/venv/lib/python3.6/site-packages/django/core/handlers/base.py", line 100, in _get_response
[Wed Jul 15 21:20:35.163674 2020] [wsgi:error] [pid 20307] [remote 122.57.27.245:55130]     resolver_match = resolver.resolve(request.path_info)
[Wed Jul 15 21:20:35.163678 2020] [wsgi:error] [pid 20307] [remote 122.57.27.245:55130]   File "/var/www/bcde215_assessment/venv/lib/python3.6/site-packages/django/urls/resolvers.py", line 544, in resolve
[Wed Jul 15 21:20:35.163682 2020] [wsgi:error] [pid 20307] [remote 122.57.27.245:55130]     for pattern in self.url_patterns:
[Wed Jul 15 21:20:35.163686 2020] [wsgi:error] [pid 20307] [remote 122.57.27.245:55130]   File "/var/www/bcde215_assessment/venv/lib/python3.6/site-packages/django/utils/functional.py", line 48, in __get__
[Wed Jul 15 21:20:35.163689 2020] [wsgi:error] [pid 20307] [remote 122.57.27.245:55130]     res = instance.__dict__[self.name] = self.func(instance)
[Wed Jul 15 21:20:35.163693 2020] [wsgi:error] [pid 20307] [remote 122.57.27.245:55130]   File "/var/www/bcde215_assessment/venv/lib/python3.6/site-packages/django/urls/resolvers.py", line 588, in url_patterns
[Wed Jul 15 21:20:35.163697 2020] [wsgi:error] [pid 20307] [remote 122.57.27.245:55130]     patterns = getattr(self.urlconf_module, "urlpatterns", self.urlconf_module)
[Wed Jul 15 21:20:35.163700 2020] [wsgi:error] [pid 20307] [remote 122.57.27.245:55130]   File "/var/www/bcde215_assessment/venv/lib/python3.6/site-packages/django/utils/functional.py", line 48, in __get__
[Wed Jul 15 21:20:35.163704 2020] [wsgi:error] [pid 20307] [remote 122.57.27.245:55130]     res = instance.__dict__[self.name] = self.func(instance)
[Wed Jul 15 21:20:35.163708 2020] [wsgi:error] [pid 20307] [remote 122.57.27.245:55130]   File "/var/www/bcde215_assessment/venv/lib/python3.6/site-packages/django/urls/resolvers.py", line 581, in urlconf_module
[Wed Jul 15 21:20:35.163711 2020] [wsgi:error] [pid 20307] [remote 122.57.27.245:55130]     return import_module(self.urlconf_name)
[Wed Jul 15 21:20:35.163715 2020] [wsgi:error] [pid 20307] [remote 122.57.27.245:55130]   File "/usr/lib/python3.6/importlib/__init__.py", line 126, in import_module
[Wed Jul 15 21:20:35.163718 2020] [wsgi:error] [pid 20307] [remote 122.57.27.245:55130]     return _bootstrap._gcd_import(name[level:], package, level)
[Wed Jul 15 21:20:35.163722 2020] [wsgi:error] [pid 20307] [remote 122.57.27.245:55130]   File "<frozen importlib._bootstrap>", line 994, in _gcd_import
[Wed Jul 15 21:20:35.163734 2020] [wsgi:error] [pid 20307] [remote 122.57.27.245:55130]   File "<frozen importlib._bootstrap>", line 971, in _find_and_load
[Wed Jul 15 21:20:35.163738 2020] [wsgi:error] [pid 20307] [remote 122.57.27.245:55130]   File "<frozen importlib._bootstrap>", line 955, in _find_and_load_unlocked
[Wed Jul 15 21:20:35.163741 2020] [wsgi:error] [pid 20307] [remote 122.57.27.245:55130]   File "<frozen importlib._bootstrap>", line 665, in _load_unlocked
[Wed Jul 15 21:20:35.163745 2020] [wsgi:error] [pid 20307] [remote 122.57.27.245:55130]   File "<frozen importlib._bootstrap_external>", line 674, in exec_module
[Wed Jul 15 21:20:35.163748 2020] [wsgi:error] [pid 20307] [remote 122.57.27.245:55130]   File "<frozen importlib._bootstrap_external>", line 781, in get_code
[Wed Jul 15 21:20:35.163752 2020] [wsgi:error] [pid 20307] [remote 122.57.27.245:55130]   File "<frozen importlib._bootstrap_external>", line 741, in source_to_code
[Wed Jul 15 21:20:35.163755 2020] [wsgi:error] [pid 20307] [remote 122.57.27.245:55130]   File "<frozen importlib._bootstrap>", line 219, in _call_with_frames_removed
[Wed Jul 15 21:20:35.163759 2020] [wsgi:error] [pid 20307] [remote 122.57.27.245:55130]   File "/var/www/bcde215_assessment/django/nzhealth/nzhealth/urls.py", line 34
[Wed Jul 15 21:20:35.163763 2020] [wsgi:error] [pid 20307] [remote 122.57.27.245:55130]     ,
[Wed Jul 15 21:20:35.163766 2020] [wsgi:error] [pid 20307] [remote 122.57.27.245:55130]     ^
[Wed Jul 15 21:20:35.163771 2020] [wsgi:error] [pid 20307] [remote 122.57.27.245:55130] SyntaxError: invalid syntax
[Wed Jul 15 21:20:35.163778 2020] [wsgi:error] [pid 20307] [remote 122.57.27.245:55130] 
[Wed Jul 15 21:20:58.272904 2020] [wsgi:error] [pid 20307] [remote 122.57.27.245:55137] Not Found: /
[Wed Jul 15 21:21:14.571938 2020] [wsgi:error] [pid 20307] [remote 122.57.27.245:55138] Not Found: /
[Wed Jul 15 21:21:16.157497 2020] [wsgi:error] [pid 20307] [remote 122.57.27.245:55138] Not Found: /
Exception ignored in: <bound method BaseEventLoop.__del__ of <_UnixSelectorEventLoop running=False closed=False debug=False>>
Traceback (most recent call last):
  File "/usr/lib/python3.6/asyncio/base_events.py", line 526, in __del__
NameError: name 'ResourceWarning' is not defined
[Wed Jul 15 21:25:44.237423 2020] [wsgi:error] [pid 20383] [remote 122.57.27.245:55175] Not Found: /news
Exception ignored in: <bound method BaseEventLoop.__del__ of <_UnixSelectorEventLoop running=False closed=False debug=False>>
Traceback (most recent call last):
  File "/usr/lib/python3.6/asyncio/base_events.py", line 526, in __del__
NameError: name 'ResourceWarning' is not defined
Exception ignored in: <bound method BaseEventLoop.__del__ of <_UnixSelectorEventLoop running=False closed=False debug=False>>
Traceback (most recent call last):
  File "/usr/lib/python3.6/asyncio/base_events.py", line 526, in __del__
NameError: name 'ResourceWarning' is not defined
Exception ignored in: <bound method BaseEventLoop.__del__ of <_UnixSelectorEventLoop running=False closed=False debug=False>>
Traceback (most recent call last):
  File "/usr/lib/python3.6/asyncio/base_events.py", line 526, in __del__
NameError: name 'ResourceWarning' is not defined
Exception ignored in: <bound method BaseEventLoop.__del__ of <_UnixSelectorEventLoop running=False closed=False debug=False>>
Traceback (most recent call last):
  File "/usr/lib/python3.6/asyncio/base_events.py", line 526, in __del__
NameError: name 'ResourceWarning' is not defined
Exception ignored in: <bound method BaseEventLoop.__del__ of <_UnixSelectorEventLoop running=False closed=False debug=False>>
Traceback (most recent call last):
  File "/usr/lib/python3.6/asyncio/base_events.py", line 526, in __del__
NameError: name 'ResourceWarning' is not defined
Exception ignored in: <bound method BaseEventLoop.__del__ of <_UnixSelectorEventLoop running=False closed=False debug=False>>
Traceback (most recent call last):
  File "/usr/lib/python3.6/asyncio/base_events.py", line 526, in __del__
NameError: name 'ResourceWarning' is not defined
Exception ignored in: <bound method BaseEventLoop.__del__ of <_UnixSelectorEventLoop running=False closed=False debug=False>>
Traceback (most recent call last):
  File "/usr/lib/python3.6/asyncio/base_events.py", line 526, in __del__
NameError: name 'ResourceWarning' is not defined
Exception ignored in: <bound method BaseEventLoop.__del__ of <_UnixSelectorEventLoop running=False closed=False debug=False>>
Traceback (most recent call last):
  File "/usr/lib/python3.6/asyncio/base_events.py", line 526, in __del__
NameError: name 'ResourceWarning' is not defined
Exception ignored in: <bound method BaseEventLoop.__del__ of <_UnixSelectorEventLoop running=False closed=False debug=False>>
Traceback (most recent call last):
  File "/usr/lib/python3.6/asyncio/base_events.py", line 526, in __del__
NameError: name 'ResourceWarning' is not defined
